Workbook

Sheet Data Dictionary
A1: Data Dictionary
A2: Version 1.2 | Last updated 2026-10-24 | Added EMPLOYMENT_STATE, POSITION_ID, LOCATION_ID, and the Positions and Locations lookups | Replaces the original Metadata Repo tab. Currency: USD, stored in whole dollars; scale to $K/$M only in reports.
A4: Table | B4: Field Name | C4: Description | D4: Data Type | E4: Unit / Format | F4: Key | G4: Nullable | H4: Allowed Values / Range | I4: Source / Generation (from original repo) | J4: Example (live, from data) | K4: Blank Count (live) | L4: Notes
A5: Employees | B5: EMPLOYEE_ID | C5: Employee ID number | D5: INTEGER | E5: Whole number (displayed 0000) | F5: PK | G5: N | H5: Positive integer, unique | I5: Derived Sequentially | J5: =Employees!A2 -> 1 | K5: =COUNTA(Employees!$A:$A)-COUNTA(Employees!A:A) -> 0
A6: Employees | B6: EMPLOYEE_FIRST | C6: First name | D6: VARCHAR(50) | E6: Text | G6: N | I6: Unique | J6: =Employees!B2 -> Daniel | K6: =COUNTA(Employees!$A:$A)-COUNTA(Employees!B:B) -> 0
A7: Employees | B7: EMPLOYEE_LAST | C7: Last name | D7: VARCHAR(50) | E7: Text | G7: N | I7: Unique | J7: =Employees!C2 -> Whitaker | K7: =COUNTA(Employees!$A:$A)-COUNTA(Employees!C:C) -> 0
A8: Employees | B8: DATE_OF_BIRTH | C8: Date of birth | D8: DATE | E8: yyyy-mm-dd | G8: N | H8: Employee aged 18+ at HIRE_DATE | I8: Unique | J8: =TEXT(Employees!D2,"yyyy-mm-dd") -> 1970-08-22 | K8: =COUNTA(Employees!$A:$A)-COUNTA(Employees!D:D) -> 0 | L8: Stored as Excel date serial; load as DATE.
A9: Employees | B9: POSITION | C9: Job title | D9: VARCHAR(100) | E9: Text | F9: FK → Positions (via POSITION_ID) | G9: N | H9: One of ~118 titles; each title maps to a single LEVEL | I9: Unique | J9: =Employees!E2 -> Chief Executive Officer | K9: =COUNTA(Employees!$A:$A)-COUNTA(Employees!E:E) -> 0 | L9: Lookup built on the Positions sheet; Employees.POSITION_ID links to it. Text column retained.
A10: Employees | B10: LEVEL | C10: Level of position | D10: SMALLINT | E10: Whole number | G10: N | H10: 1 to 10 | I10: Levels 1 through 10 | J10: =Employees!F2 -> 10 | K10: =COUNTA(Employees!$A:$A)-COUNTA(Employees!F:F) -> 0
A11: Employees | B11: EMAIL | C11: Email address | D11: VARCHAR(100) | E11: first.last@ourbusiness.biz | F11: UNIQUE | G11: N | H11: Lower-case first.last@ourbusiness.biz | I11: first.last@ourbusiness.biz | J11: =Employees!G2 -> daniel.whitaker@ourbusiness.biz | K11: =COUNTA(Employees!$A:$A)-COUNTA(Employees!G:G) -> 0
A12: Employees | B12: MGR_ID | C12: Employee ID of the employee's manager | D12: INTEGER | E12: Whole number (displayed 0000) | F12: FK → Employees.EMPLOYEE_ID | G12: Y | H12: Existing EMPLOYEE_ID; blank only for the CEO | I12: Relates to another employee | J12: =Employees!H3 -> 1 | K12: =COUNTA(Employees!$A:$A)-COUNTA(Employees!H:H) -> 1 | L12: Current manager only; no manager history. Example shown from row 3 because the CEO (row 2) is blank.
A13: Employees | B13: LOCATION | C13: Work location | D13: VARCHAR(50) | E13: Text | F13: FK → Locations (via LOCATION_ID) | G13: N | H13: Remote, HQ, or a city name | I13: Remote, name of city or HQ | J13: =Employees!I2 -> HQ | K13: =COUNTA(Employees!$A:$A)-COUNTA(Employees!I:I) -> 0 | L13: Lookup built on the Locations sheet; Employees.LOCATION_ID links to it. Text column retained.
A14: Employees | B14: POSITION_ID | C14: Foreign key to the Positions lookup | D14: INTEGER | E14: Whole number (displayed 0000) | F14: FK → Positions.POSITION_ID | G14: N | H14: Existing POSITION_ID | I14: Added in v1.2 (derived) | J14: =Employees!J2 -> 118 | K14: =COUNTA(Employees!$A:$A)-COUNTA(Employees!J:J) -> 0 | L14: Derived by formula from POSITION. The POSITION text column is retained.
A15: Employees | B15: LOCATION_ID | C15: Foreign key to the Locations lookup | D15: INTEGER | E15: Whole number (displayed 0000) | F15: FK → Locations.LOCATION_ID | G15: N | H15: Existing LOCATION_ID | I15: Added in v1.2 (derived) | J15: =Employees!K2 -> 1 | K15: =COUNTA(Employees!$A:$A)-COUNTA(Employees!K:K) -> 0 | L15: Derived by formula from LOCATION. The LOCATION text column is retained.
A16: Employee_History | B16: EMPLOYEE_ID | C16: Employee ID number | D16: INTEGER | E16: Whole number (displayed 0000) | F16: FK → Employees.EMPLOYEE_ID | G16: N | H16: Existing EMPLOYEE_ID | I16: Derived Sequentially | J16: =Employee_History!A2 -> 1 | K16: =COUNTA(Employee_History!$A:$A)-COUNTA(Employee_History!A:A) -> 0 | L16: One row per employee today; for true history use effective-dated rows.
A17: Employee_History | B17: DEPARTMENT_ID | C17: Department the employee belongs to | D17: INTEGER | E17: Whole number | F17: FK → Departments.DEPARTMENT_ID | G17: N | H17: Existing DEPARTMENT_ID | I17: Derived Sequentially | J17: =Employee_History!B2 -> 100 | K17: =COUNTA(Employee_History!$A:$A)-COUNTA(Employee_History!B:B) -> 0
A18: Employee_History | B18: HIRE_DATE | C18: Date of hiring | D18: DATE | E18: yyyy-mm-dd | G18: N | H18: On or after the department FOUNDING_DATE | I18: Unique | J18: =TEXT(Employee_History!C2,"yyyy-mm-dd") -> 2019-05-07 | K18: =COUNTA(Employee_History!$A:$A)-COUNTA(Employee_History!C:C) -> 0
A19: Employee_History | B19: TERM_DATE | C19: Date of termination | D19: DATE | E19: yyyy-mm-dd | G19: Y | H19: Blank = still employed; must be on or after HIRE_DATE | I19: Unique | J19: =TEXT(Employee_History!D5,"yyyy-mm-dd") -> 2020-08-28 | K19: =COUNTA(Employee_History!$A:$A)-COUNTA(Employee_History!D:D) -> 1200 | L19: Example shown from row 5 (a terminated employee). EMPLOYMENT_STATE is derived from this field.
A20: Employee_History | B20: STATUS | C20: Status of employment | D20: VARCHAR(20) | E20: Text | G20: N | H20: Full-Time, Part-Time, Contractor | I20: Full-Time, Part-Time. Contractor | J20: =Employee_History!E2 -> Full-Time | K20: =COUNTA(Employee_History!$A:$A)-COUNTA(Employee_History!E:E) -> 0 | L20: Original repo had a typo (period instead of comma). Does not indicate terminated employees; use EMPLOYMENT_STATE.
A21: Employee_History | B21: EMPLOYMENT_STATE | C21: Employment state derived from TERM_DATE | D21: VARCHAR(10) | E21: Text | G21: N | H21: Active, Terminated | I21: Added in v1.2 (derived) | J21: =Employee_History!F2 -> Active | K21: =COUNTA(Employee_History!$A:$A)-COUNTA(Employee_History!F:F) -> 0 | L21: Formula: Active if TERM_DATE is blank, otherwise Terminated. Resolves STATUS not reflecting terminations.
A22: Compensation | B22: EMPLOYEE_ID | C22: Employee ID number | D22: INTEGER | E22: Whole number (displayed 0000) | F22: FK → Employees.EMPLOYEE_ID | G22: N | H22: Existing EMPLOYEE_ID | I22: Derived Sequentially | J22: =Compensation!A2 -> 1 | K22: =COUNTA(Compensation!$A:$A)-COUNTA(Compensation!A:A) -> 0 | L22: One row per employee; no effective date.
A23: Compensation | B23: SALARY | C23: Salary | D23: DECIMAL(12,2) | E23: USD, whole dollars (no scaling) | G23: N | H23: Greater than 0 | I23: Unique | J23: =Compensation!B2 -> 520000 | K23: =COUNTA(Compensation!$A:$A)-COUNTA(Compensation!B:B) -> 0 | L23: CORRECTED: original repo said "Thousands" but values are whole dollars. Annual salary (confirmed by data owner).
A24: Compensation | B24: PERF_RATING | C24: Performance rating | D24: SMALLINT | E24: Whole number | G24: N | H24: 1 to 5 | I24: Ratings 1 through 5 | J24: =Compensation!C2 -> 4 | K24: =COUNTA(Compensation!$A:$A)-COUNTA(Compensation!C:C) -> 0
A25: Departments | B25: DEPARTMENT_ID | C25: Department ID number | D25: INTEGER | E25: Whole number | F25: PK | G25: N | H25: Positive integer, unique | I25: Derived Sequentially | J25: =Departments!A2 -> 100 | K25: =COUNTA(Departments!$A:$A)-COUNTA(Departments!A:A) -> 0
A26: Departments | B26: DEPARTMENT_NAME | C26: Department name | D26: VARCHAR(100) | E26: Text | F26: UNIQUE | G26: N | I26: Unique | J26: =Departments!B2 -> Executive | K26: =COUNTA(Departments!$A:$A)-COUNTA(Departments!B:B) -> 0
A27: Departments | B27: BUDGET_2025 | C27: Department budget for 2025 | D27: DECIMAL(15,2) | E27: USD, whole dollars (no scaling) | G27: N | H27: Greater than or equal to 0 | I27: Unique (as BUDGET) | J27: =Departments!C2 -> 3000000 | K27: =COUNTA(Departments!$A:$A)-COUNTA(Departments!C:C) -> 0 | L27: CORRECTED: original repo said "Millions" and had a single BUDGET field. Recommend long format (DEPARTMENT_ID, FISCAL_YEAR, BUDGET_USD).
A28: Departments | B28: BUDGET_2026 | C28: Department budget for 2026 | D28: DECIMAL(15,2) | E28: USD, whole dollars (no scaling) | G28: N | H28: Greater than or equal to 0 | I28: Unique (as BUDGET) | J28: =Departments!D2 -> 3100000 | K28: =COUNTA(Departments!$A:$A)-COUNTA(Departments!D:D) -> 0 | L28: See BUDGET_2025.
A29: Departments | B29: BUDGET_2027 | C29: Department budget for 2027 | D29: DECIMAL(15,2) | E29: USD, whole dollars (no scaling) | G29: N | H29: Greater than or equal to 0 | I29: Unique (as BUDGET) | J29: =Departments!E2 -> 3200000 | K29: =COUNTA(Departments!$A:$A)-COUNTA(Departments!E:E) -> 0 | L29: See BUDGET_2025.
A30: Departments | B30: FOUNDING_DATE | C30: Date the department was founded | D30: DATE | E30: yyyy-mm-dd | G30: N | H30: On or before earliest HIRE_DATE in the department | I30: Not in original repo | J30: =TEXT(Departments!F2,"yyyy-mm-dd") -> 2019-05-07 | K30: =COUNTA(Departments!$A:$A)-COUNTA(Departments!F:F) -> 0 | L30: Added to the dictionary; was undocumented.
A31: Departments | B31: PARENT_DEPARTMENT_ID | C31: ID of the parent department | D31: INTEGER | E31: Whole number | F31: FK → Departments.DEPARTMENT_ID | G31: Y | H31: Existing DEPARTMENT_ID; blank only for the root (Executive) | I31: Unique | J31: =Departments!G3 -> 100 | K31: =COUNTA(Departments!$A:$A)-COUNTA(Departments!G:G) -> 1 | L31: Self-referencing hierarchy. Example shown from row 3 because the root department (row 2) is blank.
A32: Departments | B32: HEADCOUNT | C32: Current headcount of the department | D32: INTEGER | E32: Whole number | G32: N | H32: Equals active employees (blank TERM_DATE) in Employee_History | I32: Not in original repo (derived by formula in v1.2) | J32: =Departments!H2 -> 8 | K32: =COUNTA(Departments!$A:$A)-COUNTA(Departments!H:H) -> 0 | L32: Now a formula: count of Active employees per department (EMPLOYMENT_STATE). Derived; do not load as source data.
A33: Positions | B33: POSITION_ID | C33: Position ID number | D33: INTEGER | E33: Whole number (displayed 0000) | F33: PK | G33: N | H33: Positive integer, unique | I33: Added in v1.2 (new lookup table) | J33: =Positions!A2 -> 1 | K33: =COUNTA(Positions!$A:$A)-COUNTA(Positions!A:A) -> 0 | L33: Lookup table listing each distinct job title once.
A34: Positions | B34: POSITION_TITLE | C34: Job title | D34: VARCHAR(100) | E34: Text | F34: UNIQUE | G34: N | H34: Distinct titles used in Employees.POSITION | I34: Added in v1.2 | J34: =Positions!B2 -> Accounting Clerk | K34: =COUNTA(Positions!$A:$A)-COUNTA(Positions!B:B) -> 0
A35: Positions | B35: LEVEL | C35: Level of the position | D35: SMALLINT | E35: Whole number | G35: N | H35: 1 to 10 | I35: Added in v1.2 (derived from Employees) | J35: =Positions!C2 -> 1 | K35: =COUNTA(Positions!$A:$A)-COUNTA(Positions!C:C) -> 0 | L35: Derived by formula; each title maps to exactly one level.
A36: Positions | B36: EMPLOYEE_COUNT | C36: Number of employees ever holding the title | D36: INTEGER | E36: Whole number | G36: N | H36: 0 or more | I36: Added in v1.2 (derived) | J36: =Positions!D2 -> 2 | K36: =COUNTA(Positions!$A:$A)-COUNTA(Positions!D:D) -> 0 | L36: Reporting column derived by formula; do not load as source data.
A37: Positions | B37: ACTIVE_COUNT | C37: Number of currently active employees in the title | D37: INTEGER | E37: Whole number | G37: N | H37: 0 or more | I37: Added in v1.2 (derived) | J37: =Positions!E2 -> 2 | K37: =COUNTA(Positions!$A:$A)-COUNTA(Positions!E:E) -> 0 | L37: Reporting column derived by formula; do not load as source data.
A38: Locations | B38: LOCATION_ID | C38: Location ID number | D38: INTEGER | E38: Whole number (displayed 0000) | F38: PK | G38: N | H38: Positive integer, unique | I38: Added in v1.2 (new lookup table) | J38: =Locations!A2 -> 1 | K38: =COUNTA(Locations!$A:$A)-COUNTA(Locations!A:A) -> 0 | L38: Lookup table listing each distinct location once.
A39: Locations | B39: LOCATION_NAME | C39: Location name | D39: VARCHAR(50) | E39: Text | F39: UNIQUE | G39: N | H39: Distinct values used in Employees.LOCATION | I39: Added in v1.2 | J39: =Locations!B2 -> HQ | K39: =COUNTA(Locations!$A:$A)-COUNTA(Locations!B:B) -> 0
A40: Locations | B40: LOCATION_TYPE | C40: Type of location | D40: VARCHAR(10) | E40: Text | G40: N | H40: HQ, Site, Remote | I40: Added in v1.2 | J40: =Locations!C2 -> HQ | K40: =COUNTA(Locations!$A:$A)-COUNTA(Locations!C:C) -> 0 | L40: Site = a named city other than HQ. State and country can be added when available.
A41: Locations | B41: EMPLOYEE_COUNT | C41: Number of employees ever at the location | D41: INTEGER | E41: Whole number | G41: N | H41: 0 or more | I41: Added in v1.2 (derived) | J41: =Locations!D2 -> 335 | K41: =COUNTA(Locations!$A:$A)-COUNTA(Locations!D:D) -> 0 | L41: Reporting column derived by formula; do not load as source data.
...

Sheet Employees
A1: EMPLOYEE_ID | B1: EMPLOYEE_FIRST | C1: EMPLOYEE_LAST | D1: DATE_OF_BIRTH | E1: POSITION | F1: LEVEL | G1: EMAIL | H1: MGR_ID | I1: LOCATION | J1: POSITION_ID | K1: LOCATION_ID
A2: 1 | B2: Daniel | C2: Whitaker | D2: 25802 | E2: Chief Executive Officer | F2: 10 | G2: daniel.whitaker@ourbusiness.biz | I2: HQ | J2: =INDEX(Positions!$A:$A,MATCH(E2,Positions!$B:$B,0)) -> 118 | K2: =INDEX(Locations!$A:$A,MATCH(I2,Locations!$B:$B,0)) -> 1
A3: 2 | B3: Priya | C3: Raman | D3: 27071 | E3: Chief Operating Officer | F3: 9 | G3: priya.raman@ourbusiness.biz | H3: 1 | I3: HQ | J3: =INDEX(Positions!$A:$A,MATCH(E3,Positions!$B:$B,0)) -> 114 | K3: =INDEX(Locations!$A:$A,MATCH(I3,Locations!$B:$B,0)) -> 1
A4: 3 | B4: Lauren | C4: Mitchell | D4: 32324 | E4: Executive Assistant | F4: 3 | G4: lauren.mitchell@ourbusiness.biz | H4: 1 | I4: HQ | J4: =INDEX(Positions!$A:$A,MATCH(E4,Positions!$B:$B,0)) -> 37 | K4: =INDEX(Locations!$A:$A,MATCH(I4,Locations!$B:$B,0)) -> 1
A5: 4 | B5: Gregory | C5: Hanson | D5: 26608 | E5: Chief Technology Officer | F5: 9 | G5: gregory.hanson@ourbusiness.biz | H5: 1 | I5: HQ | J5: =INDEX(Positions!$A:$A,MATCH(E5,Positions!$B:$B,0)) -> 116 | K5: =INDEX(Locations!$A:$A,MATCH(I5,Locations!$B:$B,0)) -> 1
A6: 5 | B6: Susan | C6: Delgado | D6: 26773 | E6: Chief Financial Officer | F6: 9 | G6: susan.delgado@ourbusiness.biz | H6: 1 | I6: HQ | J6: =INDEX(Positions!$A:$A,MATCH(E6,Positions!$B:$B,0)) -> 112 | K6: =INDEX(Locations!$A:$A,MATCH(I6,Locations!$B:$B,0)) -> 1
A7: 6 | B7: Marcus | C7: Johnson | D7: 27645 | E7: Chief Revenue Officer | F7: 9 | G7: marcus.johnson@ourbusiness.biz | H7: 1 | I7: HQ | J7: =INDEX(Positions!$A:$A,MATCH(E7,Positions!$B:$B,0)) -> 115 | K7: =INDEX(Locations!$A:$A,MATCH(I7,Locations!$B:$B,0)) -> 1
A8: 7 | B8: Elena | C8: Petrov | D8: 28150 | E8: Chief Human Resources Officer | F8: 9 | G8: elena.petrov@ourbusiness.biz | H8: 1 | I8: HQ | J8: =INDEX(Positions!$A:$A,MATCH(E8,Positions!$B:$B,0)) -> 113 | K8: =INDEX(Locations!$A:$A,MATCH(I8,Locations!$B:$B,0)) -> 1
A9: 8 | B9: Wei | C9: Zhang | D9: 27954 | E9: Chief Technology Officer | F9: 9 | G9: wei.zhang@ourbusiness.biz | H9: 1 | I9: HQ | J9: =INDEX(Positions!$A:$A,MATCH(E9,Positions!$B:$B,0)) -> 116 | K9: =INDEX(Locations!$A:$A,MATCH(I9,Locations!$B:$B,0)) -> 1
A10: 9 | B10: Olivia | C10: Brennan | D10: 27730 | E10: General Counsel | F10: 9 | G10: olivia.brennan@ourbusiness.biz | H10: 1 | I10: HQ | J10: =INDEX(Positions!$A:$A,MATCH(E10,Positions!$B:$B,0)) -> 117 | K10: =INDEX(Locations!$A:$A,MATCH(I10,Locations!$B:$B,0)) -> 1
A11: 10 | B11: Kenneth | C11: Novak | D11: 35813 | E11: Production Associate | F11: 1 | G11: kenneth.novak@ourbusiness.biz | H11: 12 | I11: Dayton | J11: =INDEX(Positions!$A:$A,MATCH(E11,Positions!$B:$B,0)) -> 6 | K11: =INDEX(Locations!$A:$A,MATCH(I11,Locations!$B:$B,0)) -> 6
A12: 11 | B12: Kenneth | C12: West | D12: 34027 | E12: Production Associate | F12: 1 | G12: kenneth.west@ourbusiness.biz | H12: 12 | I12: Reno | J12: =INDEX(Positions!$A:$A,MATCH(E12,Positions!$B:$B,0)) -> 6 | K12: =INDEX(Locations!$A:$A,MATCH(I12,Locations!$B:$B,0)) -> 11
A13: 12 | B13: Joe | C13: Delgado | D13: 27968 | E13: VP of Manufacturing | F13: 8 | G13: joe.delgado@ourbusiness.biz | H13: 2 | I13: HQ | J13: =INDEX(Positions!$A:$A,MATCH(E13,Positions!$B:$B,0)) -> 109 | K13: =INDEX(Locations!$A:$A,MATCH(I13,Locations!$B:$B,0)) -> 1
A14: 13 | B14: Steven | C14: Holmes | D14: 31990 | E14: Machine Operator | F14: 2 | G14: steven.holmes@ourbusiness.biz | H14: 12 | I14: Dayton | J14: =INDEX(Positions!$A:$A,MATCH(E14,Positions!$B:$B,0)) -> 19 | K14: =INDEX(Locations!$A:$A,MATCH(I14,Locations!$B:$B,0)) -> 6
... A1514: 1513 | B1514: Joan | C1514: Hamilton | D1514: 34025 | E1514: Maintenance Technician | F1514: 3 | G1514: joan.hamilton@ourbusiness.biz | H1514: 1497 | I1514: Greenville | J1514: =INDEX(Positions!$A:$A,MATCH(E1514,Positions!$B:$B,0)) -> 42 | K1514: =INDEX(Locations!$A:$A,MATCH(I1514,Locations!$B:$B,0)) -> 8

Sheet Employee_History
A1: EMPLOYEE_ID | B1: DEPARTMENT_ID | C1: HIRE_DATE | D1: TERM_DATE | E1: STATUS | F1: EMPLOYMENT_STATE
A2: 1 | B2: 100 | C2: 43592 | E2: Full-Time | F2: =IF(D2="","Active","Terminated") -> Active
A3: 2 | B3: 100 | C3: 43598 | E3: Full-Time | F3: =IF(D3="","Active","Terminated") -> Active
A4: 3 | B4: 100 | C4: 43619 | E4: Full-Time | F4: =IF(D4="","Active","Terminated") -> Active
A5: 4 | B5: 100 | C5: 43633 | D5: 44071 | E5: Full-Time | F5: =IF(D5="","Active","Terminated") -> Terminated
A6: 5 | B6: 100 | C6: 43689 | E6: Full-Time | F6: =IF(D6="","Active","Terminated") -> Active
A7: 6 | B7: 100 | C7: 43878 | E7: Full-Time | F7: =IF(D7="","Active","Terminated") -> Active
A8: 7 | B8: 100 | C8: 43892 | E8: Full-Time | F8: =IF(D8="","Active","Terminated") -> Active
A9: 8 | B9: 100 | C9: 44088 | E9: Full-Time | F9: =IF(D9="","Active","Terminated") -> Active
A10: 9 | B10: 100 | C10: 44270 | E10: Full-Time | F10: =IF(D10="","Active","Terminated") -> Active
A11: 10 | B11: 200 | C11: 43616 | D11: 43837 | E11: Full-Time | F11: =IF(D11="","Active","Terminated") -> Terminated
A12: 11 | B12: 200 | C12: 43640 | D12: 44306 | E12: Full-Time | F12: =IF(D12="","Active","Terminated") -> Terminated
A13: 12 | B13: 200 | C13: 43654 | E13: Full-Time | F13: =IF(D13="","Active","Terminated") -> Active
A14: 13 | B14: 200 | C14: 43668 | D14: 43700 | E14: Full-Time | F14: =IF(D14="","Active","Terminated") -> Terminated
A15: 14 | B15: 200 | C15: 43668 | D15: 44438 | E15: Full-Time | F15: =IF(D15="","Active","Terminated") -> Terminated
A16: 15 | B16: 200 | C16: 43689 | E16: Full-Time | F16: =IF(D16="","Active","Terminated") -> Active
A17: 16 | B17: 200 | C17: 43719 | D17: 44361 | E17: Full-Time | F17: =IF(D17="","Active","Terminated") -> Terminated
A18: 17 | B18: 200 | C18: 43719 | D18: 44536 | E18: Full-Time | F18: =IF(D18="","Active","Terminated") -> Terminated
A19: 18 | B19: 200 | C19: 43724 | D19: 44076 | E19: Full-Time | F19: =IF(D19="","Active","Terminated") -> Terminated
A20: 19 | B20: 200 | C20: 43726 | D20: 43818 | E20: Full-Time | F20: =IF(D20="","Active","Terminated") -> Terminated
A21: 20 | B21: 200 | C21: 43745 | D21: 44908 | E21: Full-Time | F21: =IF(D21="","Active","Terminated") -> Terminated
A22: 21 | B22: 200 | C22: 43766 | D22: 44579 | E22: Full-Time | F22: =IF(D22="","Active","Terminated") -> Terminated
A23: 22 | B23: 200 | C23: 43766 | D23: 44774 | E23: Full-Time | F23: =IF(D23="","Active","Terminated") -> Terminated
A24: 23 | B24: 200 | C24: 43787 | D24: 43892 | E24: Full-Time | F24: =IF(D24="","Active","Terminated") -> Terminated
A25: 24 | B25: 200 | C25: 43790 | D25: 44123 | E25: Full-Time | F25: =IF(D25="","Active","Terminated") -> Terminated
A26: 25 | B26: 200 | C26: 43794 | D26: 46153 | E26: Contractor | F26: =IF(D26="","Active","Terminated") -> Terminated
A27: 26 | B27: 200 | C27: 43829 | D27: 44084 | E27: Full-Time | F27: =IF(D27="","Active","Terminated") -> Terminated
A28: 27 | B28: 200 | C28: 43829 | D28: 45643 | E28: Full-Time | F28: =IF(D28="","Active","Terminated") -> Terminated
... A65: 64 | B65: 200 | C65: 44540 | D65: 44642 | E65: Full-Time | F65: =IF(D65="","Active","Terminated") -> Terminated
A66: 65 | B66: 200 | C66: 44544 | E66: Full-Time | F66: =IF(D66="","Active","Terminated") -> Active
A67: 66 | B67: 200 | C67: 44550 | D67: 45159 | E67: Full-Time | F67: =IF(D67="","Active","Terminated") -> Terminated
A68: 67 | B68: 200 | C68: 44557 | D68: 45215 | E68: Full-Time | F68: =IF(D68="","Active","Terminated") -> Terminated
A69: 68 | B69: 200 | C69: 44557 | D69: 44823 | E69: Full-Time | F69: =IF(D69="","Active","Terminated") -> Terminated
A70: 69 | B70: 200 | C70: 44564 | D70: 44753 | E70: Full-Time | F70: =IF(D70="","Active","Terminated") -> Terminated
A71: 70 | B71: 200 | C71: 44575 | D71: 44711 | E71: Full-Time | F71: =IF(D71="","Active","Terminated") -> Terminated
A72: 71 | B72: 200 | C72: 44599 | D72: 44853 | E72: Full-Time | F72: =IF(D72="","Active","Terminated") -> Terminated
A73: 72 | B73: 200 | C73: 44603 | D73: 45320 | E73: Full-Time | F73: =IF(D73="","Active","Terminated") -> Terminated
A74: 73 | B74: 200 | C74: 44613 | D74: 45345 | E74: Full-Time | F74: =IF(D74="","Active","Terminated") -> Terminated
A75: 74 | B75: 200 | C75: 44635 | D75: 45040 | E75: Contractor | F75: =IF(D75="","Active","Terminated") -> Terminated
A76: 75 | B76: 200 | C76: 44669 | D76: 46227 | E76: Full-Time | F76: =IF(D76="","Active","Terminated") -> Terminated
...

Sheet Compensation
A1: EMPLOYEE_ID | B1: SALARY | C1: PERF_RATING
A2: 1 | B2: 520000 | C2: 4
A3: 2 | B3: 340000 | C3: 5
A4: 3 | B4: 72000 | C4: 4
A5: 4 | B5: 335000 | C5: 3
A6: 5 | B6: 335000 | C6: 4
A7: 6 | B7: 325000 | C7: 4
A8: 7 | B8: 255000 | C8: 3
A9: 8 | B9: 340000 | C9: 4
A10: 9 | B10: 270000 | C10: 4
A11: 10 | B11: 30000 | C11: 4
A12: 11 | B12: 30500 | C12: 3
A13: 12 | B13: 216000 | C13: 5
... A1514: 1513 | B1514: 53000 | C1514: 3

Sheet Departments
A1: DEPARTMENT_ID | B1: DEPARTMENT_NAME | C1: BUDGET_2025 | D1: BUDGET_2026 | E1: BUDGET_2027 | F1: FOUNDING_DATE | G1: PARENT_DEPARTMENT_ID | H1: HEADCOUNT
A2: 100 | B2: Executive | C2: 3000000 | D2: 3100000 | E2: 3200000 | F2: 43592 | H2: =COUNTIFS(Employee_History!$B:$B,A2,Employee_History!$F:$F,"Active") -> 8
A3: 200 | B3: Manufacturing | C3: 41200000 | D3: 42900000 | E3: 45000000 | F3: 43592 | G3: 100 | H3: =COUNTIFS(Employee_History!$B:$B,A3,Employee_History!$F:$F,"Active") -> 480
A4: 300 | B4: Shipping | C4: 11300000 | D4: 12000000 | E4: 13000000 | F4: 43592 | G4: 200 | H4: =COUNTIFS(Employee_History!$B:$B,A4,Employee_History!$F:$F,"Active") -> 110
A5: 400 | B5: Sales | C5: 10700000 | D5: 11500000 | E5: 12500000 | F5: 44020 | G5: 100 | H5: =COUNTIFS(Employee_History!$B:$B,A5,Employee_History!$F:$F,"Active") -> 90
A6: 500 | B6: Finance | C6: 3300000 | D6: 3400000 | E6: 3500000 | F6: 44020 | G6: 100 | H6: =COUNTIFS(Employee_History!$B:$B,A6,Employee_History!$F:$F,"Active") -> 25
A7: 600 | B7: Accounting | C7: 4200000 | D7: 4300000 | E7: 4500000 | F7: 44020 | G7: 500 | H7: =COUNTIFS(Employee_History!$B:$B,A7,Employee_History!$F:$F,"Active") -> 40
A8: 700 | B8: Human Resources | C8: 3600000 | D8: 3800000 | E8: 4000000 | F8: 44020 | G8: 100 | H8: =COUNTIFS(Employee_History!$B:$B,A8,Employee_History!$F:$F,"Active") -> 25
A9: 800 | B9: Marketing | C9: 6300000 | D9: 7000000 | E9: 8000000 | F9: 44232 | G9: 400 | H9: =COUNTIFS(Employee_History!$B:$B,A9,Employee_History!$F:$F,"Active") -> 35
A10: 900 | B10: Engineering/R&D | C10: 16400000 | D10: 18000000 | E10: 20000000 | F10: 44232 | G10: 100 | H10: =COUNTIFS(Employee_History!$B:$B,A10,Employee_History!$F:$F,"Active") -> 120
A11: 1000 | B11: Procurement | C11: 2800000 | D11: 2900000 | E11: 3000000 | F11: 44232 | G11: 200 | H11: =COUNTIFS(Employee_History!$B:$B,A11,Employee_History!$F:$F,"Active") -> 30
A12: 1100 | B12: Customer Support | C12: 5100000 | D12: 5500000 | E12: 6000000 | F12: 44232 | G12: 400 | H12: =COUNTIFS(Employee_History!$B:$B,A12,Employee_History!$F:$F,"Active") -> 80
A13: 1200 | B13: Information Technology | C13: 8700000 | D13: 9700000 | E13: 11000000 | F13: 45079 | G13: 500 | H13: =COUNTIFS(Employee_History!$B:$B,A13,Employee_History!$F:$F,"Active") -> 55
A14: 1300 | B14: Quality Assurance | C14: 4500000 | D14: 4700000 | E14: 5000000 | F14: 45079 | G14: 200 | H14: =COUNTIFS(Employee_History!$B:$B,A14,Employee_History!$F:$F,"Active") -> 50
... A16: 1500 | B16: Facilities | C16: 6600000 | D16: 7400000 | E16: 7000000 | F16: 45079 | G16: 200 | H16: =COUNTIFS(Employee_History!$B:$B,A16,Employee_History!$F:$F,"Active") -> 40

Sheet Positions
A1: POSITION_ID | B1: POSITION_TITLE | C1: LEVEL | D1: EMPLOYEE_COUNT | E1: ACTIVE_COUNT
A2: 1 | B2: Accounting Clerk | C2: =INDEX(Employees!$F:$F,MATCH(B2,Employees!$E:$E,0)) -> 1 | D2: =COUNTIF(Employees!$E:$E,B2) -> 2 | E2: {=SUMPRODUCT((Employees!$E$2:$E$1514=B2)*(_xlfn.XLOOKUP(Employees!$A$2:$A$1514,Employee_History!$A$2:$A$1514,Employee_History!$F$2:$F$1514,"")="Active"))} -> 2
A3: 2 | B3: Custodian | C3: =INDEX(Employees!$F:$F,MATCH(B3,Employees!$E:$E,0)) -> 1 | D3: =COUNTIF(Employees!$E:$E,B3) -> 8 | E3: {=SUMPRODUCT((Employees!$E$2:$E$1514=B3)*(_xlfn.XLOOKUP(Employees!$A$2:$A$1514,Employee_History!$A$2:$A$1514,Employee_History!$F$2:$F$1514,"")="Active"))} -> 6
A4: 3 | B4: Groundskeeper | C4: =INDEX(Employees!$F:$F,MATCH(B4,Employees!$E:$E,0)) -> 1 | D4: =COUNTIF(Employees!$E:$E,B4) -> 7 | E4: {=SUMPRODUCT((Employees!$E$2:$E$1514=B4)*(_xlfn.XLOOKUP(Employees!$A$2:$A$1514,Employee_History!$A$2:$A$1514,Employee_History!$F$2:$F$1514,"")="Active"))} -> 5
A5: 4 | B5: Help Desk Analyst | C5: =INDEX(Employees!$F:$F,MATCH(B5,Employees!$E:$E,0)) -> 1 | D5: =COUNTIF(Employees!$E:$E,B5) -> 10 | E5: {=SUMPRODUCT((Employees!$E$2:$E$1514=B5)*(_xlfn.XLOOKUP(Employees!$A$2:$A$1514,Employee_History!$A$2:$A$1514,Employee_History!$F$2:$F$1514,"")="Active"))} -> 8
A6: 5 | B6: Inside Sales Associate | C6: =INDEX(Employees!$F:$F,MATCH(B6,Employees!$E:$E,0)) -> 1 | D6: =COUNTIF(Employees!$E:$E,B6) -> 13 | E6: {=SUMPRODUCT((Employees!$E$2:$E$1514=B6)*(_xlfn.XLOOKUP(Employees!$A$2:$A$1514,Employee_History!$A$2:$A$1514,Employee_History!$F$2:$F$1514,"")="Active"))} -> 9
A7: 6 | B7: Production Associate | C7: =INDEX(Employees!$F:$F,MATCH(B7,Employees!$E:$E,0)) -> 1 | D7: =COUNTIF(Employees!$E:$E,B7) -> 199 | E7: {=SUMPRODUCT((Employees!$E$2:$E$1514=B7)*(_xlfn.XLOOKUP(Employees!$A$2:$A$1514,Employee_History!$A$2:$A$1514,Employee_History!$F$2:$F$1514,"")="Active"))} -> 139
A8: 7 | B8: QA Technician | C8: =INDEX(Employees!$F:$F,MATCH(B8,Employees!$E:$E,0)) -> 1 | D8: =COUNTIF(Employees!$E:$E,B8) -> 9 | E8: {=SUMPRODUCT((Employees!$E$2:$E$1514=B8)*(_xlfn.XLOOKUP(Employees!$A$2:$A$1514,Employee_History!$A$2:$A$1514,Employee_History!$F$2:$F$1514,"")="Active"))} -> 7
A9: 8 | B9: Tier 1 Support Agent | C9: =INDEX(Employees!$F:$F,MATCH(B9,Employees!$E:$E,0)) -> 1 | D9: =COUNTIF(Employees!$E:$E,B9) -> 50 | E9: {=SUMPRODUCT((Employees!$E$2:$E$1514=B9)*(_xlfn.XLOOKUP(Employees!$A$2:$A$1514,Employee_History!$A$2:$A$1514,Employee_History!$F$2:$F$1514,"")="Active"))} -> 31
A10: 9 | B10: Warehouse Associate | C10: =INDEX(Employees!$F:$F,MATCH(B10,Employees!$E:$E,0)) -> 1 | D10: =COUNTIF(Employees!$E:$E,B10) -> 66 | E10: {=SUMPRODUCT((Employees!$E$2:$E$1514=B10)*(_xlfn.XLOOKUP(Employees!$A$2:$A$1514,Employee_History!$A$2:$A$1514,Employee_History!$F$2:$F$1514,"")="Active"))} -> 44
A11: 10 | B11: Accounts Payable Specialist | C11: =INDEX(Employees!$F:$F,MATCH(B11,Employees!$E:$E,0)) -> 2 | D11: =COUNTIF(Employees!$E:$E,B11) -> 9 | E11: {=SUMPRODUCT((Employees!$E$2:$E$1514=B11)*(_xlfn.XLOOKUP(Employees!$A$2:$A$1514,Employee_History!$A$2:$A$1514,Employee_History!$F$2:$F$1514,"")="Active"))} -> 8
A12: 11 | B12: Accounts Receivable Specialist | C12: =INDEX(Employees!$F:$F,MATCH(B12,Employees!$E:$E,0)) -> 2 | D12: =COUNTIF(Employees!$E:$E,B12) -> 5 | E12: {=SUMPRODUCT((Employees!$E$2:$E$1514=B12)*(_xlfn.XLOOKUP(Employees!$A$2:$A$1514,Employee_History!$A$2:$A$1514,Employee_History!$F$2:$F$1514,"")="Active"))} -> 4
A13: 12 | B13: Associate Engineer | C13: =INDEX(Employees!$F:$F,MATCH(B13,Employees!$E:$E,0)) -> 2 | D13: =COUNTIF(Employees!$E:$E,B13) -> 22 | E13: {=SUMPRODUCT((Employees!$E$2:$E$1514=B13)*(_xlfn.XLOOKUP(Employees!$A$2:$A$1514,Employee_History!$A$2:$A$1514,Employee_History!$F$2:$F$1514,"")="Active"))} -> 17
... A119: 118 | B119: Chief Executive Officer | C119: =INDEX(Employees!$F:$F,MATCH(B119,Employees!$E:$E,0)) -> 10 | D119: =COUNTIF(Employees!$E:$E,B119) -> 1 | E119: {=SUMPRODUCT((Employees!$E$2:$E$1514=B119)*(_xlfn.XLOOKUP(Employees!$A$2:$A$1514,Employee_History!$A$2:$A$1514,Employee_History!$F$2:$F$1514,"")="Active"))} -> 1

Sheet Locations
A1: LOCATION_ID | B1: LOCATION_NAME | C1: LOCATION_TYPE | D1: EMPLOYEE_COUNT | E1: ACTIVE_COUNT
A2: 1 | B2: HQ | C2: HQ | D2: =COUNTIF(Employees!$I:$I,B2) -> 335 | E2: {=SUMPRODUCT((Employees!$I$2:$I$1514=B2)*(_xlfn.XLOOKUP(Employees!$A$2:$A$1514,Employee_History!$A$2:$A$1514,Employee_History!$F$2:$F$1514,"")="Active"))} -> 275
A3: 2 | B3: Atlanta | C3: Site | D3: =COUNTIF(Employees!$I:$I,B3) -> 52 | E3: {=SUMPRODUCT((Employees!$I$2:$I$1514=B3)*(_xlfn.XLOOKUP(Employees!$A$2:$A$1514,Employee_History!$A$2:$A$1514,Employee_History!$F$2:$F$1514,"")="Active"))} -> 38
A4: 3 | B4: Austin | C4: Site | D4: =COUNTIF(Employees!$I:$I,B4) -> 28 | E4: {=SUMPRODUCT((Employees!$I$2:$I$1514=B4)*(_xlfn.XLOOKUP(Employees!$A$2:$A$1514,Employee_History!$A$2:$A$1514,Employee_History!$F$2:$F$1514,"")="Active"))} -> 23
A5: 4 | B5: Chicago | C5: Site | D5: =COUNTIF(Employees!$I:$I,B5) -> 17 | E5: {=SUMPRODUCT((Employees!$I$2:$I$1514=B5)*(_xlfn.XLOOKUP(Employees!$A$2:$A$1514,Employee_History!$A$2:$A$1514,Employee_History!$F$2:$F$1514,"")="Active"))} -> 13
A6: 5 | B6: Dallas | C6: Site | D6: =COUNTIF(Employees!$I:$I,B6) -> 12 | E6: {=SUMPRODUCT((Employees!$I$2:$I$1514=B6)*(_xlfn.XLOOKUP(Employees!$A$2:$A$1514,Employee_History!$A$2:$A$1514,Employee_History!$F$2:$F$1514,"")="Active"))} -> 10
A7: 6 | B7: Dayton | C7: Site | D7: =COUNTIF(Employees!$I:$I,B7) -> 397 | E7: {=SUMPRODUCT((Employees!$I$2:$I$1514=B7)*(_xlfn.XLOOKUP(Employees!$A$2:$A$1514,Employee_History!$A$2:$A$1514,Employee_History!$F$2:$F$1514,"")="Active"))} -> 306
A8: 7 | B8: Denver | C8: Site | D8: =COUNTIF(Employees!$I:$I,B8) -> 12 | E8: {=SUMPRODUCT((Employees!$I$2:$I$1514=B8)*(_xlfn.XLOOKUP(Employees!$A$2:$A$1514,Employee_History!$A$2:$A$1514,Employee_History!$F$2:$F$1514,"")="Active"))} -> 10
A9: 8 | B9: Greenville | C9: Site | D9: =COUNTIF(Employees!$I:$I,B9) -> 236 | E9: {=SUMPRODUCT((Employees!$I$2:$I$1514=B9)*(_xlfn.XLOOKUP(Employees!$A$2:$A$1514,Employee_History!$A$2:$A$1514,Employee_History!$F$2:$F$1514,"")="Active"))} -> 185
A10: 9 | B10: Memphis | C10: Site | D10: =COUNTIF(Employees!$I:$I,B10) -> 60 | E10: {=SUMPRODUCT((Employees!$I$2:$I$1514=B10)*(_xlfn.XLOOKUP(Employees!$A$2:$A$1514,Employee_History!$A$2:$A$1514,Employee_History!$F$2:$F$1514,"")="Active"))} -> 44
A11: 10 | B11: New York | C11: Site | D11: =COUNTIF(Employees!$I:$I,B11) -> 5 | E11: {=SUMPRODUCT((Employees!$I$2:$I$1514=B11)*(_xlfn.XLOOKUP(Employees!$A$2:$A$1514,Employee_History!$A$2:$A$1514,Employee_History!$F$2:$F$1514,"")="Active"))} -> 5
A12: 11 | B12: Reno | C12: Site | D12: =COUNTIF(Employees!$I:$I,B12) -> 177 | E12: {=SUMPRODUCT((Employees!$I$2:$I$1514=B12)*(_xlfn.XLOOKUP(Employees!$A$2:$A$1514,Employee_History!$A$2:$A$1514,Employee_History!$F$2:$F$1514,"")="Active"))} -> 138
A13: 12 | B13: Remote | C13: Remote | D13: =COUNTIF(Employees!$I:$I,B13) -> 182 | E13: {=SUMPRODUCT((Employees!$I$2:$I$1514=B13)*(_xlfn.XLOOKUP(Employees!$A$2:$A$1514,Employee_History!$A$2:$A$1514,Employee_History!$F$2:$F$1514,"")="Active"))} -> 153

Sheet Data Quality
A1: Data Quality Checks
A2: Live checks against the Employees, Employee_History, Compensation, Departments, Positions and Locations sheets. Expected values are inputs (blue); Actual values are formulas.
A4: Checks failing | B4: Total checks
A5: =COUNTIF($G$8:$G$36,"FAIL") -> 0 | B5: =COUNTA($G$8:$G$36) -> 29
A7: # | B7: Category | C7: Check | D7: Table(s) | E7: Expected | F7: Actual | G7: Status | H7: Description
A8: 1 | B8: Row counts | C8: Employees row count = Employee_History row count | D8: Employees / Employee_History | E8: 0 | F8: =ROWS(Employees!$A$2:$A$1514)-ROWS(Employee_History!$A$2:$A$1514) -> 0 | G8: =IF(F8=E8,"PASS","FAIL") -> PASS | H8: Difference in row counts (Employees minus Employee_History).
A9: 2 | B9: Row counts | C9: Employees row count = Compensation row count | D9: Employees / Compensation | E9: 0 | F9: =ROWS(Employees!$A$2:$A$1514)-ROWS(Compensation!$A$2:$A$1514) -> 0 | G9: =IF(F9=E9,"PASS","FAIL") -> PASS | H9: Difference in row counts (Employees minus Compensation).
A10: 3 | B10: Uniqueness | C10: Duplicate EMPLOYEE_ID in Employees | D10: Employees | E10: 0 | F10: =ROWS(Employees!$A$2:$A$1514)-ROWS(_xlfn.UNIQUE(Employees!$A$2:$A$1514)) -> 0 | G10: =IF(F10=E10,"PASS","FAIL") -> PASS | H10: EMPLOYEE_ID must be unique (PK).
A11: 4 | B11: Uniqueness | C11: Duplicate EMAIL in Employees | D11: Employees | E11: 0 | F11: =ROWS(Employees!$G$2:$G$1514)-ROWS(_xlfn.UNIQUE(Employees!$G$2:$G$1514)) -> 0 | G11: =IF(F11=E11,"PASS","FAIL") -> PASS | H11: EMAIL must be unique.
A12: 5 | B12: Uniqueness | C12: Duplicate EMPLOYEE_ID in Employee_History | D12: Employee_History | E12: 0 | F12: =ROWS(Employee_History!$A$2:$A$1514)-ROWS(_xlfn.UNIQUE(Employee_History!$A$2:$A$1514)) -> 0 | G12: =IF(F12=E12,"PASS","FAIL") -> PASS | H12: Currently one history row per employee.
A13: 6 | B13: Uniqueness | C13: Duplicate EMPLOYEE_ID in Compensation | D13: Compensation | E13: 0 | F13: =ROWS(Compensation!$A$2:$A$1514)-ROWS(_xlfn.UNIQUE(Compensation!$A$2:$A$1514)) -> 0 | G13: =IF(F13=E13,"PASS","FAIL") -> PASS | H13: Currently one compensation row per employee.
A14: 7 | B14: Uniqueness | C14: Duplicate DEPARTMENT_ID in Departments | D14: Departments | E14: 0 | F14: =ROWS(Departments!$A$2:$A$16)-ROWS(_xlfn.UNIQUE(Departments!$A$2:$A$16)) -> 0 | G14: =IF(F14=E14,"PASS","FAIL") -> PASS | H14: DEPARTMENT_ID must be unique (PK).
A15: 8 | B15: Referential integrity | C15: Employee_History rows with no matching Employee | D15: Employee_History → Employees | E15: 0 | F15: {=SUMPRODUCT(--(COUNTIF(Employees!$A$2:$A$1514,Employee_History!$A$2:$A$1514)=0))} -> 0 | G15: =IF(F15=E15,"PASS","FAIL") -> PASS | H15: FK: Employee_History.EMPLOYEE_ID → Employees.
A16: 9 | B16: Referential integrity | C16: Employees with no Employee_History row | D16: Employees → Employee_History | E16: 0 | F16: {=SUMPRODUCT(--(COUNTIF(Employee_History!$A$2:$A$1514,Employees!$A$2:$A$1514)=0))} -> 0 | G16: =IF(F16=E16,"PASS","FAIL") -> PASS | H16: Every employee needs a history row.
A17: 10 | B17: Referential integrity | C17: Compensation rows with no matching Employee | D17: Compensation → Employees | E17: 0 | F17: {=SUMPRODUCT(--(COUNTIF(Employees!$A$2:$A$1514,Compensation!$A$2:$A$1514)=0))} -> 0 | G17: =IF(F17=E17,"PASS","FAIL") -> PASS | H17: FK: Compensation.EMPLOYEE_ID → Employees.
A18: 11 | B18: Referential integrity | C18: Employees with no Compensation row | D18: Employees → Compensation | E18: 0 | F18: {=SUMPRODUCT(--(COUNTIF(Compensation!$A$2:$A$1514,Employees!$A$2:$A$1514)=0))} -> 0 | G18: =IF(F18=E18,"PASS","FAIL") -> PASS | H18: Every employee needs a compensation row.
A19: 12 | B19: Referential integrity | C19: MGR_ID not found in Employees | D19: Employees → Employees | E19: 0 | F19: {=SUMPRODUCT((Employees!$H$2:$H$1514<>"")*(COUNTIF(Employees!$A$2:$A$1514,Employees!$H$2:$H$1514)=0))} -> 0 | G19: =IF(F19=E19,"PASS","FAIL") -> PASS | H19: FK: Employees.MGR_ID → Employees.
A20: 13 | B20: Referential integrity | C20: Employees with blank MGR_ID | D20: Employees | E20: 1 | F20: =COUNTBLANK(Employees!$H$2:$H$1514) -> 1 | G20: =IF(F20=E20,"PASS","FAIL") -> PASS | H20: Expected: 1 (the CEO).
A21: 14 | B21: Referential integrity | C21: Employee_History DEPARTMENT_ID not in Departments | D21: Employee_History → Departments | E21: 0 | F21: {=SUMPRODUCT(--(COUNTIF(Departments!$A$2:$A$16,Employee_History!$B$2:$B$1514)=0))} -> 0 | G21: =IF(F21=E21,"PASS","FAIL") -> PASS | H21: FK: Employee_History.DEPARTMENT_ID → Departments.
A22: 15 | B22: Referential integrity | C22: PARENT_DEPARTMENT_ID not in Departments | D22: Departments → Departments | E22: 0 | F22: {=SUMPRODUCT((Departments!$G$2:$G$16<>"")*(COUNTIF(Departments!$A$2:$A$16,Departments!$G$2:$G$16)=0))} -> 0 | G22: =IF(F22=E22,"PASS","FAIL") -> PASS | H22: FK: self-referencing department hierarchy.
A23: 16 | B23: Referential integrity | C23: Departments with blank PARENT_DEPARTMENT_ID | D23: Departments | E23: 1 | F23: =COUNTBLANK(Departments!$G$2:$G$16) -> 1 | G23: =IF(F23=E23,"PASS","FAIL") -> PASS | H23: Expected: 1 (root department).
A24: 17 | B24: Referential integrity | C24: Employees with POSITION_ID or LOCATION_ID not found | D24: Employees → Positions / Locations | E24: 0 | F24: {=SUMPRODUCT(--ISNA(Employees!$J$2:$J$1514))+SUMPRODUCT(--ISNA(Employees!$K$2:$K$1514))} -> 0 | G24: =IF(F24=E24,"PASS","FAIL") -> PASS | H24: Lookup coverage for Positions and Locations.
A25: 18 | B25: Domain | C25: LEVEL outside 1 to 10 | D25: Employees | E25: 0 | F25: =COUNTIFS(Employees!$F$2:$F$1514,"<1")+COUNTIFS(Employees!$F$2:$F$1514,">10")+ROWS(Employees!$A$2:$A$1514)-COUNT(Employees!$F$2:$F$1514) -> 0 | G25: =IF(F25=E25,"PASS","FAIL") -> PASS | H25: Includes non-numeric or blank values.
A26: 19 | B26: Domain | C26: PERF_RATING outside 1 to 5 | D26: Compensation | E26: 0 | F26: =COUNTIFS(Compensation!$C$2:$C$1514,"<1")+COUNTIFS(Compensation!$C$2:$C$1514,">5")+ROWS(Compensation!$A$2:$A$1514)-COUNT(Compensation!$C$2:$C$1514) -> 0 | G26: =IF(F26=E26,"PASS","FAIL") -> PASS | H26: Includes non-numeric or blank values.
A27: 20 | B27: Domain | C27: SALARY blank, non-numeric or not positive | D27: Compensation | E27: 0 | F27: =COUNTIFS(Compensation!$B$2:$B$1514,"<=0")+ROWS(Compensation!$A$2:$A$1514)-COUNT(Compensation!$B$2:$B$1514) -> 0 | G27: =IF(F27=E27,"PASS","FAIL") -> PASS | H27: SALARY must be a positive number.
A28: 21 | B28: Domain | C28: STATUS not Full-Time, Part-Time or Contractor | D28: Employee_History | E28: 0 | F28: =ROWS(Employee_History!$E$2:$E$1514)-COUNTIF(Employee_History!$E$2:$E$1514,"Full-Time")-COUNTIF(Employee_History!$E$2:$E$1514,"Part-Time")-COUNTIF(Employee_History!$E$2:$E$1514,"Contractor") -> 0 | G28: =IF(F28=E28,"PASS","FAIL") -> PASS | H28: Allowed values per the Data Dictionary.
A29: 22 | B29: Domain | C29: EMAIL not matching first.last@ourbusiness.biz | D29: Employees | E29: 0 | F29: {=SUMPRODUCT(--(Employees!$G$2:$G$1514<>LOWER(Employees!$B$2:$B$1514&"."&Employees!$C$2:$C$1514&"@ourbusiness.biz")))} -> 0 | G29: =IF(F29=E29,"PASS","FAIL") -> PASS | H29: Email follows the naming convention.
A30: 23 | B30: Dates | C30: TERM_DATE before HIRE_DATE | D30: Employee_History | E30: 0 | F30: {=SUMPRODUCT((Employee_History!$D$2:$D$1514<>"")*(Employee_History!$D$2:$D$1514<Employee_History!$C$2:$C$1514))} -> 0 | G30: =IF(F30=E30,"PASS","FAIL") -> PASS | H30: Termination cannot precede hiring.
A31: 24 | B31: Dates | C31: HIRE_DATE before department FOUNDING_DATE | D31: Employee_History / Departments | E31: 0 | F31: {=SUMPRODUCT(--(Employee_History!$C$2:$C$1514<SUMIF(Departments!$A$2:$A$16,Employee_History!$B$2:$B$1514,Departments!$F$2:$F$16)))} -> 0 | G31: =IF(F31=E31,"PASS","FAIL") -> PASS | H31: Employee cannot join a department before it existed.
A32: 25 | B32: Dates | C32: Employees aged under 18 at HIRE_DATE | D32: Employee_History / Employees | E32: 0 | F32: {=SUMPRODUCT(--((Employee_History!$C$2:$C$1514-_xlfn.XLOOKUP(Employee_History!$A$2:$A$1514,Employees!$A$2:$A$1514,Employees!$D$2:$D$1514))/365.25<18))} -> 0 | G32: =IF(F32=E32,"PASS","FAIL") -> PASS | H32: Uses DATE_OF_BIRTH from Employees.
A33: 26 | B33: Business logic | C33: Active employees whose manager is terminated | D33: Employees / Employee_History | E33: 0 | F33: {=SUMPRODUCT((Employees!$H$2:$H$1514<>"")*(_xlfn.XLOOKUP(Employees!$H$2:$H$1514,Employee_History!$A$2:$A$1514,Employee_History!$F$2:$F$1514,"")="Terminated")*(_xlfn.XLOOKUP(Employees!$A$2:$A$1514,Employee_History!$A$2:$A$1514,Employee_History!$F$2:$F$1514,"")="Active"))} -> 0 | G33: =IF(F33=E33,"PASS","FAIL") -> PASS | H33: Reporting lines should be reassigned on termination.
A34: 27 | B34: Business logic | C34: Sum of department HEADCOUNT − active employees | D34: Departments / Employee_History | E34: 0 | F34: =SUM(Departments!$H$2:$H$16)-COUNTIF(Employee_History!$F$2:$F$1514,"Active") -> 0 | G34: =IF(F34=E34,"PASS","FAIL") -> PASS | H34: Department headcount ties to the active employee count.
A35: 28 | B35: Business logic | C35: Positions mapped to more than one LEVEL | D35: Employees | E35: 0 | F35: {=SUMPRODUCT(--(COUNTIFS(Employees!$E$2:$E$1514,Employees!$E$2:$E$1514,Employees!$F$2:$F$1514,"<>"&Employees!$F$2:$F$1514)>0))} -> 0 | G35: =IF(F35=E35,"PASS","FAIL") -> PASS | H35: Each job title should have a single level.
A36: 29 | B36: Business logic | C36: Employee counts: Positions and Locations vs Employees | D36: Positions / Locations / Employees | E36: 0 | F36: =ABS(SUM(Positions!$D$2:$D$119)-ROWS(Employees!$A$2:$A$1514))+ABS(SUM(Locations!$D$2:$D$13)-ROWS(Employees!$A$2:$A$1514)) -> 0 | G36: =IF(F36=E36,"PASS","FAIL") -> PASS | H36: Lookup tables account for every employee.
