Workbook

Sheet Data Dictionary
A1: Data Dictionary
A2: Version 1.3 | Last updated 2026-10-24 | Removed Employees.POSITION, LEVEL and LOCATION (use POSITION_ID / LOCATION_ID and Positions.JOB_LEVEL); renamed LEVEL to JOB_LEVEL and STATUS to EMPLOYMENT_TYPE; POSITION_ID, LOCATION_ID and JOB_LEVEL are now stored values; SALARY and BUDGET_* typed INTEGER; employee 897 (VP of Marketing) now reports to the Chief Revenue Officer (ID 6). Currency: USD, stored in whole dollars; scale to $K/$M only in reports.
A4: Table | B4: Field Name | C4: Description | D4: Data Type | E4: Unit / Format | F4: Key | G4: Nullable | H4: Allowed Values / Range | I4: Source / Generation (from original repo) | J4: Example (live, from data) | K4: Blank Count (live) | L4: Notes
A5: Employees | B5: EMPLOYEE_ID | C5: Employee ID number | D5: INTEGER | E5: Whole number (displayed 0000) | F5: PK | G5: N | H5: Positive integer, unique | I5: Derived Sequentially | J5: =Employees!A2 | K5: =COUNTA(Employees!$A:$A)-COUNTA(Employees!A:A)
A6: Employees | B6: EMPLOYEE_FIRST | C6: First name | D6: VARCHAR(50) | E6: Text | G6: N | I6: Unique | J6: =Employees!B2 | K6: =COUNTA(Employees!$A:$A)-COUNTA(Employees!B:B)
A7: Employees | B7: EMPLOYEE_LAST | C7: Last name | D7: VARCHAR(50) | E7: Text | G7: N | I7: Unique | J7: =Employees!C2 | K7: =COUNTA(Employees!$A:$A)-COUNTA(Employees!C:C)
A8: Employees | B8: DATE_OF_BIRTH | C8: Date of birth | D8: DATE | E8: yyyy-mm-dd | G8: N | H8: Employee aged 18+ at HIRE_DATE | I8: Unique | J8: =TEXT(Employees!D2,"yyyy-mm-dd") | K8: =COUNTA(Employees!$A:$A)-COUNTA(Employees!D:D) | L8: Stored as Excel date serial; load as DATE.
A9: Employees | B9: EMAIL | C9: Email address | D9: VARCHAR(100) | E9: first.last@ourbusiness.biz | F9: UNIQUE | G9: N | H9: Lower-case first.last@ourbusiness.biz | I9: first.last@ourbusiness.biz | J9: =Employees!E2 | K9: =COUNTA(Employees!$A:$A)-COUNTA(Employees!E:E)
A10: Employees | B10: MGR_ID | C10: Employee ID of the employee's manager | D10: INTEGER | E10: Whole number (displayed 0000) | F10: FK → Employees.EMPLOYEE_ID | G10: Y | H10: Existing EMPLOYEE_ID; blank only for the CEO | I10: Relates to another employee | J10: =Employees!F3 | K10: =COUNTA(Employees!$A:$A)-COUNTA(Employees!F:F) | L10: Current manager only; no manager history. Example shown from row 3 because the CEO (row 2) is blank.
A11: Employees | B11: POSITION_ID | C11: Foreign key to the Positions lookup | D11: INTEGER | E11: Whole number (displayed 0000) | F11: FK → Positions.POSITION_ID | G11: N | H11: Existing POSITION_ID | I11: Added in v1.2; stored value in v1.3 | J11: =Employees!G2 | K11: =COUNTA(Employees!$A:$A)-COUNTA(Employees!G:G) | L11: Stored value (was a formula in v1.2). Join to Positions for the job title. The POSITION text column was removed in v1.3.
A12: Employees | B12: LOCATION_ID | C12: Foreign key to the Locations lookup | D12: INTEGER | E12: Whole number (displayed 0000) | F12: FK → Locations.LOCATION_ID | G12: N | H12: Existing LOCATION_ID | I12: Added in v1.2; stored value in v1.3 | J12: =Employees!H2 | K12: =COUNTA(Employees!$A:$A)-COUNTA(Employees!H:H) | L12: Stored value (was a formula in v1.2). Join to Locations for the location name. The LOCATION text column was removed in v1.3.
A13: Employee_History | B13: EMPLOYEE_ID | C13: Employee ID number | D13: INTEGER | E13: Whole number (displayed 0000) | F13: FK → Employees.EMPLOYEE_ID | G13: N | H13: Existing EMPLOYEE_ID | I13: Derived Sequentially | J13: =Employee_History!A2 | K13: =COUNTA(Employee_History!$A:$A)-COUNTA(Employee_History!A:A) | L13: One row per employee today; for true history use effective-dated rows.
A14: Employee_History | B14: DEPARTMENT_ID | C14: Department the employee belongs to | D14: INTEGER | E14: Whole number | F14: FK → Departments.DEPARTMENT_ID | G14: N | H14: Existing DEPARTMENT_ID | I14: Derived Sequentially | J14: =Employee_History!B2 | K14: =COUNTA(Employee_History!$A:$A)-COUNTA(Employee_History!B:B)
A15: Employee_History | B15: HIRE_DATE | C15: Date of hiring | D15: DATE | E15: yyyy-mm-dd | G15: N | H15: On or after the department FOUNDING_DATE | I15: Unique | J15: =TEXT(Employee_History!C2,"yyyy-mm-dd") | K15: =COUNTA(Employee_History!$A:$A)-COUNTA(Employee_History!C:C)
A16: Employee_History | B16: TERM_DATE | C16: Date of termination | D16: DATE | E16: yyyy-mm-dd | G16: Y | H16: Blank = still employed; must be on or after HIRE_DATE | I16: Unique | J16: =TEXT(Employee_History!D5,"yyyy-mm-dd") | K16: =COUNTA(Employee_History!$A:$A)-COUNTA(Employee_History!D:D) | L16: Example shown from row 5 (a terminated employee). EMPLOYMENT_STATE is derived from this field.
A17: Employee_History | B17: EMPLOYMENT_TYPE | C17: Type of employment | D17: VARCHAR(20) | E17: Text | G17: N | H17: Full-Time, Part-Time, Contractor | I17: Full-Time, Part-Time. Contractor | J17: =Employee_History!E2 | K17: =COUNTA(Employee_History!$A:$A)-COUNTA(Employee_History!E:E) | L17: Renamed from STATUS in v1.3 to avoid confusion with EMPLOYMENT_STATE. Original repo had a typo (period instead of comma). Does not indicate terminated employees; use EMPLOYMENT_STATE.
A18: Employee_History | B18: EMPLOYMENT_STATE | C18: Employment state derived from TERM_DATE | D18: VARCHAR(10) | E18: Text | G18: N | H18: Active, Terminated | I18: Added in v1.2 (derived) | J18: =Employee_History!F2 | K18: =COUNTA(Employee_History!$A:$A)-COUNTA(Employee_History!F:F) | L18: Formula: Active if TERM_DATE is blank, otherwise Terminated. Resolves EMPLOYMENT_TYPE not reflecting terminations.
A19: Compensation | B19: EMPLOYEE_ID | C19: Employee ID number | D19: INTEGER | E19: Whole number (displayed 0000) | F19: FK → Employees.EMPLOYEE_ID | G19: N | H19: Existing EMPLOYEE_ID | I19: Derived Sequentially | J19: =Compensation!A2 | K19: =COUNTA(Compensation!$A:$A)-COUNTA(Compensation!A:A) | L19: One row per employee; no effective date.
A20: Compensation | B20: SALARY | C20: Salary | D20: INTEGER | E20: USD, whole dollars (no scaling) | G20: N | H20: Greater than 0 | I20: Unique | J20: =Compensation!B2 | K20: =COUNTA(Compensation!$A:$A)-COUNTA(Compensation!B:B) | L20: CORRECTED: original repo said "Thousands" but values are whole dollars. Annual salary (confirmed by data owner).
A21: Compensation | B21: PERF_RATING | C21: Performance rating | D21: SMALLINT | E21: Whole number | G21: N | H21: 1 to 5 | I21: Ratings 1 through 5 | J21: =Compensation!C2 | K21: =COUNTA(Compensation!$A:$A)-COUNTA(Compensation!C:C)
A22: Departments | B22: DEPARTMENT_ID | C22: Department ID number | D22: INTEGER | E22: Whole number | F22: PK | G22: N | H22: Positive integer, unique | I22: Derived Sequentially | J22: =Departments!A2 | K22: =COUNTA(Departments!$A:$A)-COUNTA(Departments!A:A)
A23: Departments | B23: DEPARTMENT_NAME | C23: Department name | D23: VARCHAR(100) | E23: Text | F23: UNIQUE | G23: N | I23: Unique | J23: =Departments!B2 | K23: =COUNTA(Departments!$A:$A)-COUNTA(Departments!B:B)
A24: Departments | B24: BUDGET_2025 | C24: Department budget for 2025 | D24: INTEGER | E24: USD, whole dollars (no scaling) | G24: N | H24: Greater than or equal to 0 | I24: Unique (as BUDGET) | J24: =Departments!C2 | K24: =COUNTA(Departments!$A:$A)-COUNTA(Departments!C:C) | L24: CORRECTED: original repo said "Millions" and had a single BUDGET field. Recommend long format (DEPARTMENT_ID, FISCAL_YEAR, BUDGET_USD).
A25: Departments | B25: BUDGET_2026 | C25: Department budget for 2026 | D25: INTEGER | E25: USD, whole dollars (no scaling) | G25: N | H25: Greater than or equal to 0 | I25: Unique (as BUDGET) | J25: =Departments!D2 | K25: =COUNTA(Departments!$A:$A)-COUNTA(Departments!D:D) | L25: See BUDGET_2025.
A26: Departments | B26: BUDGET_2027 | C26: Department budget for 2027 | D26: INTEGER | E26: USD, whole dollars (no scaling) | G26: N | H26: Greater than or equal to 0 | I26: Unique (as BUDGET) | J26: =Departments!E2 | K26: =COUNTA(Departments!$A:$A)-COUNTA(Departments!E:E) | L26: See BUDGET_2025.
A27: Departments | B27: FOUNDING_DATE | C27: Date the department was founded | D27: DATE | E27: yyyy-mm-dd | G27: N | H27: On or before earliest HIRE_DATE in the department | I27: Not in original repo | J27: =TEXT(Departments!F2,"yyyy-mm-dd") | K27: =COUNTA(Departments!$A:$A)-COUNTA(Departments!F:F) | L27: Added to the dictionary; was undocumented.
A28: Departments | B28: PARENT_DEPARTMENT_ID | C28: ID of the parent department | D28: INTEGER | E28: Whole number | F28: FK → Departments.DEPARTMENT_ID | G28: Y | H28: Existing DEPARTMENT_ID; blank only for the root (Executive) | I28: Unique | J28: =Departments!G3 | K28: =COUNTA(Departments!$A:$A)-COUNTA(Departments!G:G) | L28: Self-referencing hierarchy. Example shown from row 3 because the root department (row 2) is blank.
A29: Departments | B29: HEADCOUNT | C29: Current headcount of the department | D29: INTEGER | E29: Whole number | G29: N | H29: Equals active employees (blank TERM_DATE) in Employee_History | I29: Not in original repo (derived by formula in v1.2) | J29: =Departments!H2 | K29: =COUNTA(Departments!$A:$A)-COUNTA(Departments!H:H) | L29: Now a formula: count of Active employees per department (EMPLOYMENT_STATE). Derived; do not load as source data.
A30: Positions | B30: POSITION_ID | C30: Position ID number | D30: INTEGER | E30: Whole number (displayed 0000) | F30: PK | G30: N | H30: Positive integer, unique | I30: Added in v1.2 (new lookup table) | J30: =Positions!A2 | K30: =COUNTA(Positions!$A:$A)-COUNTA(Positions!A:A) | L30: Lookup table listing each distinct job title once.
A31: Positions | B31: POSITION_TITLE | C31: Job title | D31: VARCHAR(100) | E31: Text | F31: UNIQUE | G31: N | H31: Distinct job titles (one row per title) | I31: Added in v1.2 | J31: =Positions!B2 | K31: =COUNTA(Positions!$A:$A)-COUNTA(Positions!B:B)
A32: Positions | B32: JOB_LEVEL | C32: Job level of the position | D32: SMALLINT | E32: Whole number | G32: N | H32: 1 to 10 | I32: Added in v1.2; stored value in v1.3 | J32: =Positions!C2 | K32: =COUNTA(Positions!$A:$A)-COUNTA(Positions!C:C) | L32: Source of truth for job level (was derived in v1.2; also removed from Employees in v1.3). Renamed from LEVEL to avoid the Oracle reserved word. Each title has exactly one level.
A33: Positions | B33: EMPLOYEE_COUNT | C33: Number of employees ever holding the title | D33: INTEGER | E33: Whole number | G33: N | H33: 0 or more | I33: Added in v1.2 (derived) | J33: =Positions!D2 | K33: =COUNTA(Positions!$A:$A)-COUNTA(Positions!D:D) | L33: Reporting column derived by formula; do not load as source data.
A34: Positions | B34: ACTIVE_COUNT | C34: Number of currently active employees in the title | D34: INTEGER | E34: Whole number | G34: N | H34: 0 or more | I34: Added in v1.2 (derived) | J34: =Positions!E2 | K34: =COUNTA(Positions!$A:$A)-COUNTA(Positions!E:E) | L34: Reporting column derived by formula; do not load as source data.
A35: Locations | B35: LOCATION_ID | C35: Location ID number | D35: INTEGER | E35: Whole number (displayed 0000) | F35: PK | G35: N | H35: Positive integer, unique | I35: Added in v1.2 (new lookup table) | J35: =Locations!A2 | K35: =COUNTA(Locations!$A:$A)-COUNTA(Locations!A:A) | L35: Lookup table listing each distinct location once.
A36: Locations | B36: LOCATION_NAME | C36: Location name | D36: VARCHAR(50) | E36: Text | F36: UNIQUE | G36: N | H36: Distinct location names (one row per location) | I36: Added in v1.2 | J36: =Locations!B2 | K36: =COUNTA(Locations!$A:$A)-COUNTA(Locations!B:B)
A37: Locations | B37: LOCATION_TYPE | C37: Type of location | D37: VARCHAR(10) | E37: Text | G37: N | H37: HQ, Site, Remote | I37: Added in v1.2 | J37: =Locations!C2 | K37: =COUNTA(Locations!$A:$A)-COUNTA(Locations!C:C) | L37: Site = a named city other than HQ. State and country can be added when available.
A38: Locations | B38: EMPLOYEE_COUNT | C38: Number of employees ever at the location | D38: INTEGER | E38: Whole number | G38: N | H38: 0 or more | I38: Added in v1.2 (derived) | J38: =Locations!D2 | K38: =COUNTA(Locations!$A:$A)-COUNTA(Locations!D:D) | L38: Reporting column derived by formula; do not load as source data.
A39: Locations | B39: ACTIVE_COUNT | C39: Number of currently active employees at the location | D39: INTEGER | E39: Whole number | G39: N | H39: 0 or more | I39: Added in v1.2 (derived) | J39: =Locations!E2 | K39: =COUNTA(Locations!$A:$A)-COUNTA(Locations!E:E) | L39: Reporting column derived by formula; do not load as source data.

Sheet Employees
A1: EMPLOYEE_ID | B1: EMPLOYEE_FIRST | C1: EMPLOYEE_LAST | D1: DATE_OF_BIRTH | E1: EMAIL | F1: MGR_ID | G1: POSITION_ID | H1: LOCATION_ID
A2: 1 | B2: Daniel | C2: Whitaker | D2: 25802 | E2: daniel.whitaker@ourbusiness.biz | G2: 118 | H2: 1
A3: 2 | B3: Priya | C3: Raman | D3: 27071 | E3: priya.raman@ourbusiness.biz | F3: 1 | G3: 114 | H3: 1
A4: 3 | B4: Lauren | C4: Mitchell | D4: 32324 | E4: lauren.mitchell@ourbusiness.biz | F4: 1 | G4: 37 | H4: 1
A5: 4 | B5: Gregory | C5: Hanson | D5: 26608 | E5: gregory.hanson@ourbusiness.biz | F5: 1 | G5: 116 | H5: 1
A6: 5 | B6: Susan | C6: Delgado | D6: 26773 | E6: susan.delgado@ourbusiness.biz | F6: 1 | G6: 112 | H6: 1
A7: 6 | B7: Marcus | C7: Johnson | D7: 27645 | E7: marcus.johnson@ourbusiness.biz | F7: 1 | G7: 115 | H7: 1
A8: 7 | B8: Elena | C8: Petrov | D8: 28150 | E8: elena.petrov@ourbusiness.biz | F8: 1 | G8: 113 | H8: 1
A9: 8 | B9: Wei | C9: Zhang | D9: 27954 | E9: wei.zhang@ourbusiness.biz | F9: 1 | G9: 116 | H9: 1
A10: 9 | B10: Olivia | C10: Brennan | D10: 27730 | E10: olivia.brennan@ourbusiness.biz | F10: 1 | G10: 117 | H10: 1
A11: 10 | B11: Kenneth | C11: Novak | D11: 35813 | E11: kenneth.novak@ourbusiness.biz | F11: 12 | G11: 6 | H11: 6
A12: 11 | B12: Kenneth | C12: West | D12: 34027 | E12: kenneth.west@ourbusiness.biz | F12: 12 | G12: 6 | H12: 11
A13: 12 | B13: Joe | C13: Delgado | D13: 27968 | E13: joe.delgado@ourbusiness.biz | F13: 2 | G13: 109 | H13: 1
A14: 13 | B14: Steven | C14: Holmes | D14: 31990 | E14: steven.holmes@ourbusiness.biz | F14: 12 | G14: 19 | H14: 6
... A1514: 1513 | B1514: Joan | C1514: Hamilton | D1514: 34025 | E1514: joan.hamilton@ourbusiness.biz | F1514: 1497 | G1514: 42 | H1514: 8

Sheet Employee_History
A1: EMPLOYEE_ID | B1: DEPARTMENT_ID | C1: HIRE_DATE | D1: TERM_DATE | E1: EMPLOYMENT_TYPE | F1: EMPLOYMENT_STATE
A2: 1 | B2: 100 | C2: 43592 | E2: Full-Time | F2: =IF(D2="","Active","Terminated")
A3: 2 | B3: 100 | C3: 43598 | E3: Full-Time | F3: =IF(D3="","Active","Terminated")
A4: 3 | B4: 100 | C4: 43619 | E4: Full-Time | F4: =IF(D4="","Active","Terminated")
A5: 4 | B5: 100 | C5: 43633 | D5: 44071 | E5: Full-Time | F5: =IF(D5="","Active","Terminated")
A6: 5 | B6: 100 | C6: 43689 | E6: Full-Time | F6: =IF(D6="","Active","Terminated")
A7: 6 | B7: 100 | C7: 43878 | E7: Full-Time | F7: =IF(D7="","Active","Terminated")
A8: 7 | B8: 100 | C8: 43892 | E8: Full-Time | F8: =IF(D8="","Active","Terminated")
A9: 8 | B9: 100 | C9: 44088 | E9: Full-Time | F9: =IF(D9="","Active","Terminated")
A10: 9 | B10: 100 | C10: 44270 | E10: Full-Time | F10: =IF(D10="","Active","Terminated")
A11: 10 | B11: 200 | C11: 43616 | D11: 43837 | E11: Full-Time | F11: =IF(D11="","Active","Terminated")
A12: 11 | B12: 200 | C12: 43640 | D12: 44306 | E12: Full-Time | F12: =IF(D12="","Active","Terminated")
A13: 12 | B13: 200 | C13: 43654 | E13: Full-Time | F13: =IF(D13="","Active","Terminated")
A14: 13 | B14: 200 | C14: 43668 | D14: 43700 | E14: Full-Time | F14: =IF(D14="","Active","Terminated")
A15: 14 | B15: 200 | C15: 43668 | D15: 44438 | E15: Full-Time | F15: =IF(D15="","Active","Terminated")
A16: 15 | B16: 200 | C16: 43689 | E16: Full-Time | F16: =IF(D16="","Active","Terminated")
A17: 16 | B17: 200 | C17: 43719 | D17: 44361 | E17: Full-Time | F17: =IF(D17="","Active","Terminated")
A18: 17 | B18: 200 | C18: 43719 | D18: 44536 | E18: Full-Time | F18: =IF(D18="","Active","Terminated")
A19: 18 | B19: 200 | C19: 43724 | D19: 44076 | E19: Full-Time | F19: =IF(D19="","Active","Terminated")
A20: 19 | B20: 200 | C20: 43726 | D20: 43818 | E20: Full-Time | F20: =IF(D20="","Active","Terminated")
A21: 20 | B21: 200 | C21: 43745 | D21: 44908 | E21: Full-Time | F21: =IF(D21="","Active","Terminated")
A22: 21 | B22: 200 | C22: 43766 | D22: 44579 | E22: Full-Time | F22: =IF(D22="","Active","Terminated")
A23: 22 | B23: 200 | C23: 43766 | D23: 44774 | E23: Full-Time | F23: =IF(D23="","Active","Terminated")
A24: 23 | B24: 200 | C24: 43787 | D24: 43892 | E24: Full-Time | F24: =IF(D24="","Active","Terminated")
A25: 24 | B25: 200 | C25: 43790 | D25: 44123 | E25: Full-Time | F25: =IF(D25="","Active","Terminated")
A26: 25 | B26: 200 | C26: 43794 | D26: 46153 | E26: Contractor | F26: =IF(D26="","Active","Terminated")
A27: 26 | B27: 200 | C27: 43829 | D27: 44084 | E27: Full-Time | F27: =IF(D27="","Active","Terminated")
A28: 27 | B28: 200 | C28: 43829 | D28: 45643 | E28: Full-Time | F28: =IF(D28="","Active","Terminated")
... A65: 64 | B65: 200 | C65: 44540 | D65: 44642 | E65: Full-Time | F65: =IF(D65="","Active","Terminated")
A66: 65 | B66: 200 | C66: 44544 | E66: Full-Time | F66: =IF(D66="","Active","Terminated")
A67: 66 | B67: 200 | C67: 44550 | D67: 45159 | E67: Full-Time | F67: =IF(D67="","Active","Terminated")
A68: 67 | B68: 200 | C68: 44557 | D68: 45215 | E68: Full-Time | F68: =IF(D68="","Active","Terminated")
A69: 68 | B69: 200 | C69: 44557 | D69: 44823 | E69: Full-Time | F69: =IF(D69="","Active","Terminated")
A70: 69 | B70: 200 | C70: 44564 | D70: 44753 | E70: Full-Time | F70: =IF(D70="","Active","Terminated")
A71: 70 | B71: 200 | C71: 44575 | D71: 44711 | E71: Full-Time | F71: =IF(D71="","Active","Terminated")
A72: 71 | B72: 200 | C72: 44599 | D72: 44853 | E72: Full-Time | F72: =IF(D72="","Active","Terminated")
A73: 72 | B73: 200 | C73: 44603 | D73: 45320 | E73: Full-Time | F73: =IF(D73="","Active","Terminated")
A74: 73 | B74: 200 | C74: 44613 | D74: 45345 | E74: Full-Time | F74: =IF(D74="","Active","Terminated")
A75: 74 | B75: 200 | C75: 44635 | D75: 45040 | E75: Contractor | F75: =IF(D75="","Active","Terminated")
A76: 75 | B76: 200 | C76: 44669 | D76: 46227 | E76: Full-Time | F76: =IF(D76="","Active","Terminated")
...

Sheet Compensation
A1: EMPLOYEE_ID | B1: SALARY | C1: PERF_RATING
A2: 1 | B2: 520000 | C2: 4
A3: 2 | B3: 340000 | C3: 5
A4: 3 | B4: 72000 | C4: 4
A5: 4 | B5: 335000 | C5: 3
A6: 5 | B6: 335000 | C6: 4
A7: 6 | B7: 325000 | C7: 4
A8: 7 | B8: 255000 | C8: 3
A9: 8 | B9: 340000 | C9: 4
A10: 9 | B10: 270000 | C10: 4
A11: 10 | B11: 30000 | C11: 4
A12: 11 | B12: 30500 | C12: 3
A13: 12 | B13: 216000 | C13: 5
... A1514: 1513 | B1514: 53000 | C1514: 3

Sheet Departments
A1: DEPARTMENT_ID | B1: DEPARTMENT_NAME | C1: BUDGET_2025 | D1: BUDGET_2026 | E1: BUDGET_2027 | F1: FOUNDING_DATE | G1: PARENT_DEPARTMENT_ID | H1: HEADCOUNT
A2: 100 | B2: Executive | C2: 3000000 | D2: 3100000 | E2: 3200000 | F2: 43592 | H2: =COUNTIFS(Employee_History!$B:$B,A2,Employee_History!$F:$F,"Active")
A3: 200 | B3: Manufacturing | C3: 41200000 | D3: 42900000 | E3: 45000000 | F3: 43592 | G3: 100 | H3: =COUNTIFS(Employee_History!$B:$B,A3,Employee_History!$F:$F,"Active")
A4: 300 | B4: Shipping | C4: 11300000 | D4: 12000000 | E4: 13000000 | F4: 43592 | G4: 200 | H4: =COUNTIFS(Employee_History!$B:$B,A4,Employee_History!$F:$F,"Active")
A5: 400 | B5: Sales | C5: 10700000 | D5: 11500000 | E5: 12500000 | F5: 44020 | G5: 100 | H5: =COUNTIFS(Employee_History!$B:$B,A5,Employee_History!$F:$F,"Active")
A6: 500 | B6: Finance | C6: 3300000 | D6: 3400000 | E6: 3500000 | F6: 44020 | G6: 100 | H6: =COUNTIFS(Employee_History!$B:$B,A6,Employee_History!$F:$F,"Active")
A7: 600 | B7: Accounting | C7: 4200000 | D7: 4300000 | E7: 4500000 | F7: 44020 | G7: 500 | H7: =COUNTIFS(Employee_History!$B:$B,A7,Employee_History!$F:$F,"Active")
A8: 700 | B8: Human Resources | C8: 3600000 | D8: 3800000 | E8: 4000000 | F8: 44020 | G8: 100 | H8: =COUNTIFS(Employee_History!$B:$B,A8,Employee_History!$F:$F,"Active")
A9: 800 | B9: Marketing | C9: 6300000 | D9: 7000000 | E9: 8000000 | F9: 44232 | G9: 400 | H9: =COUNTIFS(Employee_History!$B:$B,A9,Employee_History!$F:$F,"Active")
A10: 900 | B10: Engineering/R&D | C10: 16400000 | D10: 18000000 | E10: 20000000 | F10: 44232 | G10: 100 | H10: =COUNTIFS(Employee_History!$B:$B,A10,Employee_History!$F:$F,"Active")
A11: 1000 | B11: Procurement | C11: 2800000 | D11: 2900000 | E11: 3000000 | F11: 44232 | G11: 200 | H11: =COUNTIFS(Employee_History!$B:$B,A11,Employee_History!$F:$F,"Active")
A12: 1100 | B12: Customer Support | C12: 5100000 | D12: 5500000 | E12: 6000000 | F12: 44232 | G12: 400 | H12: =COUNTIFS(Employee_History!$B:$B,A12,Employee_History!$F:$F,"Active")
A13: 1200 | B13: Information Technology | C13: 8700000 | D13: 9700000 | E13: 11000000 | F13: 45079 | G13: 500 | H13: =COUNTIFS(Employee_History!$B:$B,A13,Employee_History!$F:$F,"Active")
A14: 1300 | B14: Quality Assurance | C14: 4500000 | D14: 4700000 | E14: 5000000 | F14: 45079 | G14: 200 | H14: =COUNTIFS(Employee_History!$B:$B,A14,Employee_History!$F:$F,"Active")
... A16: 1500 | B16: Facilities | C16: 6600000 | D16: 7400000 | E16: 7000000 | F16: 45079 | G16: 200 | H16: =COUNTIFS(Employee_History!$B:$B,A16,Employee_History!$F:$F,"Active")

Sheet Positions
A1: POSITION_ID | B1: POSITION_TITLE | C1: JOB_LEVEL | D1: EMPLOYEE_COUNT | E1: ACTIVE_COUNT
A2: 1 | B2: Accounting Clerk | C2: 1 | D2: =COUNTIF(Employees!$G:$G,A2) | E2: {=SUMPRODUCT((Employees!$G$2:$G$1514=A2)*(_xlfn.XLOOKUP(Employees!$A$2:$A$1514,Employee_History!$A$2:$A$1514,Employee_History!$F$2:$F$1514,"")="Active"))}
A3: 2 | B3: Custodian | C3: 1 | D3: =COUNTIF(Employees!$G:$G,A3) | E3: {=SUMPRODUCT((Employees!$G$2:$G$1514=A3)*(_xlfn.XLOOKUP(Employees!$A$2:$A$1514,Employee_History!$A$2:$A$1514,Employee_History!$F$2:$F$1514,"")="Active"))}
A4: 3 | B4: Groundskeeper | C4: 1 | D4: =COUNTIF(Employees!$G:$G,A4) | E4: {=SUMPRODUCT((Employees!$G$2:$G$1514=A4)*(_xlfn.XLOOKUP(Employees!$A$2:$A$1514,Employee_History!$A$2:$A$1514,Employee_History!$F$2:$F$1514,"")="Active"))}
A5: 4 | B5: Help Desk Analyst | C5: 1 | D5: =COUNTIF(Employees!$G:$G,A5) | E5: {=SUMPRODUCT((Employees!$G$2:$G$1514=A5)*(_xlfn.XLOOKUP(Employees!$A$2:$A$1514,Employee_History!$A$2:$A$1514,Employee_History!$F$2:$F$1514,"")="Active"))}
A6: 5 | B6: Inside Sales Associate | C6: 1 | D6: =COUNTIF(Employees!$G:$G,A6) | E6: {=SUMPRODUCT((Employees!$G$2:$G$1514=A6)*(_xlfn.XLOOKUP(Employees!$A$2:$A$1514,Employee_History!$A$2:$A$1514,Employee_History!$F$2:$F$1514,"")="Active"))}
A7: 6 | B7: Production Associate | C7: 1 | D7: =COUNTIF(Employees!$G:$G,A7) | E7: {=SUMPRODUCT((Employees!$G$2:$G$1514=A7)*(_xlfn.XLOOKUP(Employees!$A$2:$A$1514,Employee_History!$A$2:$A$1514,Employee_History!$F$2:$F$1514,"")="Active"))}
A8: 7 | B8: QA Technician | C8: 1 | D8: =COUNTIF(Employees!$G:$G,A8) | E8: {=SUMPRODUCT((Employees!$G$2:$G$1514=A8)*(_xlfn.XLOOKUP(Employees!$A$2:$A$1514,Employee_History!$A$2:$A$1514,Employee_History!$F$2:$F$1514,"")="Active"))}
A9: 8 | B9: Tier 1 Support Agent | C9: 1 | D9: =COUNTIF(Employees!$G:$G,A9) | E9: {=SUMPRODUCT((Employees!$G$2:$G$1514=A9)*(_xlfn.XLOOKUP(Employees!$A$2:$A$1514,Employee_History!$A$2:$A$1514,Employee_History!$F$2:$F$1514,"")="Active"))}
A10: 9 | B10: Warehouse Associate | C10: 1 | D10: =COUNTIF(Employees!$G:$G,A10) | E10: {=SUMPRODUCT((Employees!$G$2:$G$1514=A10)*(_xlfn.XLOOKUP(Employees!$A$2:$A$1514,Employee_History!$A$2:$A$1514,Employee_History!$F$2:$F$1514,"")="Active"))}
A11: 10 | B11: Accounts Payable Specialist | C11: 2 | D11: =COUNTIF(Employees!$G:$G,A11) | E11: {=SUMPRODUCT((Employees!$G$2:$G$1514=A11)*(_xlfn.XLOOKUP(Employees!$A$2:$A$1514,Employee_History!$A$2:$A$1514,Employee_History!$F$2:$F$1514,"")="Active"))}
A12: 11 | B12: Accounts Receivable Specialist | C12: 2 | D12: =COUNTIF(Employees!$G:$G,A12) | E12: {=SUMPRODUCT((Employees!$G$2:$G$1514=A12)*(_xlfn.XLOOKUP(Employees!$A$2:$A$1514,Employee_History!$A$2:$A$1514,Employee_History!$F$2:$F$1514,"")="Active"))}
A13: 12 | B13: Associate Engineer | C13: 2 | D13: =COUNTIF(Employees!$G:$G,A13) | E13: {=SUMPRODUCT((Employees!$G$2:$G$1514=A13)*(_xlfn.XLOOKUP(Employees!$A$2:$A$1514,Employee_History!$A$2:$A$1514,Employee_History!$F$2:$F$1514,"")="Active"))}
... A119: 118 | B119: Chief Executive Officer | C119: 10 | D119: =COUNTIF(Employees!$G:$G,A119) | E119: {=SUMPRODUCT((Employees!$G$2:$G$1514=A119)*(_xlfn.XLOOKUP(Employees!$A$2:$A$1514,Employee_History!$A$2:$A$1514,Employee_History!$F$2:$F$1514,"")="Active"))}

Sheet Locations
A1: LOCATION_ID | B1: LOCATION_NAME | C1: LOCATION_TYPE | D1: EMPLOYEE_COUNT | E1: ACTIVE_COUNT
A2: 1 | B2: HQ | C2: HQ | D2: =COUNTIF(Employees!$H:$H,A2) | E2: {=SUMPRODUCT((Employees!$H$2:$H$1514=A2)*(_xlfn.XLOOKUP(Employees!$A$2:$A$1514,Employee_History!$A$2:$A$1514,Employee_History!$F$2:$F$1514,"")="Active"))}
A3: 2 | B3: Atlanta | C3: Site | D3: =COUNTIF(Employees!$H:$H,A3) | E3: {=SUMPRODUCT((Employees!$H$2:$H$1514=A3)*(_xlfn.XLOOKUP(Employees!$A$2:$A$1514,Employee_History!$A$2:$A$1514,Employee_History!$F$2:$F$1514,"")="Active"))}
A4: 3 | B4: Austin | C4: Site | D4: =COUNTIF(Employees!$H:$H,A4) | E4: {=SUMPRODUCT((Employees!$H$2:$H$1514=A4)*(_xlfn.XLOOKUP(Employees!$A$2:$A$1514,Employee_History!$A$2:$A$1514,Employee_History!$F$2:$F$1514,"")="Active"))}
A5: 4 | B5: Chicago | C5: Site | D5: =COUNTIF(Employees!$H:$H,A5) | E5: {=SUMPRODUCT((Employees!$H$2:$H$1514=A5)*(_xlfn.XLOOKUP(Employees!$A$2:$A$1514,Employee_History!$A$2:$A$1514,Employee_History!$F$2:$F$1514,"")="Active"))}
A6: 5 | B6: Dallas | C6: Site | D6: =COUNTIF(Employees!$H:$H,A6) | E6: {=SUMPRODUCT((Employees!$H$2:$H$1514=A6)*(_xlfn.XLOOKUP(Employees!$A$2:$A$1514,Employee_History!$A$2:$A$1514,Employee_History!$F$2:$F$1514,"")="Active"))}
A7: 6 | B7: Dayton | C7: Site | D7: =COUNTIF(Employees!$H:$H,A7) | E7: {=SUMPRODUCT((Employees!$H$2:$H$1514=A7)*(_xlfn.XLOOKUP(Employees!$A$2:$A$1514,Employee_History!$A$2:$A$1514,Employee_History!$F$2:$F$1514,"")="Active"))}
A8: 7 | B8: Denver | C8: Site | D8: =COUNTIF(Employees!$H:$H,A8) | E8: {=SUMPRODUCT((Employees!$H$2:$H$1514=A8)*(_xlfn.XLOOKUP(Employees!$A$2:$A$1514,Employee_History!$A$2:$A$1514,Employee_History!$F$2:$F$1514,"")="Active"))}
A9: 8 | B9: Greenville | C9: Site | D9: =COUNTIF(Employees!$H:$H,A9) | E9: {=SUMPRODUCT((Employees!$H$2:$H$1514=A9)*(_xlfn.XLOOKUP(Employees!$A$2:$A$1514,Employee_History!$A$2:$A$1514,Employee_History!$F$2:$F$1514,"")="Active"))}
A10: 9 | B10: Memphis | C10: Site | D10: =COUNTIF(Employees!$H:$H,A10) | E10: {=SUMPRODUCT((Employees!$H$2:$H$1514=A10)*(_xlfn.XLOOKUP(Employees!$A$2:$A$1514,Employee_History!$A$2:$A$1514,Employee_History!$F$2:$F$1514,"")="Active"))}
A11: 10 | B11: New York | C11: Site | D11: =COUNTIF(Employees!$H:$H,A11) | E11: {=SUMPRODUCT((Employees!$H$2:$H$1514=A11)*(_xlfn.XLOOKUP(Employees!$A$2:$A$1514,Employee_History!$A$2:$A$1514,Employee_History!$F$2:$F$1514,"")="Active"))}
A12: 11 | B12: Reno | C12: Site | D12: =COUNTIF(Employees!$H:$H,A12) | E12: {=SUMPRODUCT((Employees!$H$2:$H$1514=A12)*(_xlfn.XLOOKUP(Employees!$A$2:$A$1514,Employee_History!$A$2:$A$1514,Employee_History!$F$2:$F$1514,"")="Active"))}
A13: 12 | B13: Remote | C13: Remote | D13: =COUNTIF(Employees!$H:$H,A13) | E13: {=SUMPRODUCT((Employees!$H$2:$H$1514=A13)*(_xlfn.XLOOKUP(Employees!$A$2:$A$1514,Employee_History!$A$2:$A$1514,Employee_History!$F$2:$F$1514,"")="Active"))}

Sheet Data Quality
A1: Data Quality Checks
A2: Live checks against the Employees, Employee_History, Compensation, Departments, Positions and Locations sheets. Expected values are inputs (blue); Actual values are formulas.
A4: Checks failing | B4: Total checks
A5: =COUNTIF($G$8:$G$36,"FAIL") | B5: =COUNTA($G$8:$G$36)
A7: # | B7: Category | C7: Check | D7: Table(s) | E7: Expected | F7: Actual | G7: Status | H7: Description
A8: 1 | B8: Row counts | C8: Employees row count = Employee_History row count | D8: Employees / Employee_History | E8: 0 | F8: =ROWS(Employees!$A$2:$A$1514)-ROWS(Employee_History!$A$2:$A$1514) | G8: =IF(F8=E8,"PASS","FAIL") | H8: Difference in row counts (Employees minus Employee_History).
A9: 2 | B9: Row counts | C9: Employees row count = Compensation row count | D9: Employees / Compensation | E9: 0 | F9: =ROWS(Employees!$A$2:$A$1514)-ROWS(Compensation!$A$2:$A$1514) | G9: =IF(F9=E9,"PASS","FAIL") | H9: Difference in row counts (Employees minus Compensation).
A10: 3 | B10: Uniqueness | C10: Duplicate EMPLOYEE_ID in Employees | D10: Employees | E10: 0 | F10: =ROWS(Employees!$A$2:$A$1514)-ROWS(_xlfn.UNIQUE(Employees!$A$2:$A$1514)) | G10: =IF(F10=E10,"PASS","FAIL") | H10: EMPLOYEE_ID must be unique (PK).
A11: 4 | B11: Uniqueness | C11: Duplicate EMAIL in Employees | D11: Employees | E11: 0 | F11: =ROWS(Employees!$E$2:$E$1514)-ROWS(_xlfn.UNIQUE(Employees!$E$2:$E$1514)) | G11: =IF(F11=E11,"PASS","FAIL") | H11: EMAIL must be unique.
A12: 5 | B12: Uniqueness | C12: Duplicate EMPLOYEE_ID in Employee_History | D12: Employee_History | E12: 0 | F12: =ROWS(Employee_History!$A$2:$A$1514)-ROWS(_xlfn.UNIQUE(Employee_History!$A$2:$A$1514)) | G12: =IF(F12=E12,"PASS","FAIL") | H12: Currently one history row per employee.
A13: 6 | B13: Uniqueness | C13: Duplicate EMPLOYEE_ID in Compensation | D13: Compensation | E13: 0 | F13: =ROWS(Compensation!$A$2:$A$1514)-ROWS(_xlfn.UNIQUE(Compensation!$A$2:$A$1514)) | G13: =IF(F13=E13,"PASS","FAIL") | H13: Currently one compensation row per employee.
A14: 7 | B14: Uniqueness | C14: Duplicate DEPARTMENT_ID in Departments | D14: Departments | E14: 0 | F14: =ROWS(Departments!$A$2:$A$16)-ROWS(_xlfn.UNIQUE(Departments!$A$2:$A$16)) | G14: =IF(F14=E14,"PASS","FAIL") | H14: DEPARTMENT_ID must be unique (PK).
A15: 8 | B15: Referential integrity | C15: Employee_History rows with no matching Employee | D15: Employee_History → Employees | E15: 0 | F15: {=SUMPRODUCT(--(COUNTIF(Employees!$A$2:$A$1514,Employee_History!$A$2:$A$1514)=0))} | G15: =IF(F15=E15,"PASS","FAIL") | H15: FK: Employee_History.EMPLOYEE_ID → Employees.
A16: 9 | B16: Referential integrity | C16: Employees with no Employee_History row | D16: Employees → Employee_History | E16: 0 | F16: {=SUMPRODUCT(--(COUNTIF(Employee_History!$A$2:$A$1514,Employees!$A$2:$A$1514)=0))} | G16: =IF(F16=E16,"PASS","FAIL") | H16: Every employee needs a history row.
A17: 10 | B17: Referential integrity | C17: Compensation rows with no matching Employee | D17: Compensation → Employees | E17: 0 | F17: {=SUMPRODUCT(--(COUNTIF(Employees!$A$2:$A$1514,Compensation!$A$2:$A$1514)=0))} | G17: =IF(F17=E17,"PASS","FAIL") | H17: FK: Compensation.EMPLOYEE_ID → Employees.
A18: 11 | B18: Referential integrity | C18: Employees with no Compensation row | D18: Employees → Compensation | E18: 0 | F18: {=SUMPRODUCT(--(COUNTIF(Compensation!$A$2:$A$1514,Employees!$A$2:$A$1514)=0))} | G18: =IF(F18=E18,"PASS","FAIL") | H18: Every employee needs a compensation row.
A19: 12 | B19: Referential integrity | C19: MGR_ID not found in Employees | D19: Employees → Employees | E19: 0 | F19: {=SUMPRODUCT((Employees!$F$2:$F$1514<>"")*(COUNTIF(Employees!$A$2:$A$1514,Employees!$F$2:$F$1514)=0))} | G19: =IF(F19=E19,"PASS","FAIL") | H19: FK: Employees.MGR_ID → Employees.
A20: 13 | B20: Referential integrity | C20: Employees with blank MGR_ID | D20: Employees | E20: 1 | F20: =COUNTBLANK(Employees!$F$2:$F$1514) | G20: =IF(F20=E20,"PASS","FAIL") | H20: Expected: 1 (the CEO).
A21: 14 | B21: Referential integrity | C21: Employee_History DEPARTMENT_ID not in Departments | D21: Employee_History → Departments | E21: 0 | F21: {=SUMPRODUCT(--(COUNTIF(Departments!$A$2:$A$16,Employee_History!$B$2:$B$1514)=0))} | G21: =IF(F21=E21,"PASS","FAIL") | H21: FK: Employee_History.DEPARTMENT_ID → Departments.
A22: 15 | B22: Referential integrity | C22: PARENT_DEPARTMENT_ID not in Departments | D22: Departments → Departments | E22: 0 | F22: {=SUMPRODUCT((Departments!$G$2:$G$16<>"")*(COUNTIF(Departments!$A$2:$A$16,Departments!$G$2:$G$16)=0))} | G22: =IF(F22=E22,"PASS","FAIL") | H22: FK: self-referencing department hierarchy.
A23: 16 | B23: Referential integrity | C23: Departments with blank PARENT_DEPARTMENT_ID | D23: Departments | E23: 1 | F23: =COUNTBLANK(Departments!$G$2:$G$16) | G23: =IF(F23=E23,"PASS","FAIL") | H23: Expected: 1 (root department).
A24: 17 | B24: Referential integrity | C24: Employees with POSITION_ID or LOCATION_ID not found | D24: Employees → Positions / Locations | E24: 0 | F24: {=SUMPRODUCT(--(COUNTIF(Positions!$A$2:$A$119,Employees!$G$2:$G$1514)=0))+SUMPRODUCT(--(COUNTIF(Locations!$A$2:$A$13,Employees!$H$2:$H$1514)=0))} | G24: =IF(F24=E24,"PASS","FAIL") | H24: Lookup coverage for Positions and Locations.
A25: 18 | B25: Domain | C25: JOB_LEVEL outside 1 to 10 | D25: Positions | E25: 0 | F25: =COUNTIFS(Positions!$C$2:$C$119,"<1")+COUNTIFS(Positions!$C$2:$C$119,">10")+ROWS(Positions!$A$2:$A$119)-COUNT(Positions!$C$2:$C$119) | G25: =IF(F25=E25,"PASS","FAIL") | H25: JOB_LEVEL on the Positions lookup must be a number from 1 to 10.
A26: 19 | B26: Domain | C26: PERF_RATING outside 1 to 5 | D26: Compensation | E26: 0 | F26: =COUNTIFS(Compensation!$C$2:$C$1514,"<1")+COUNTIFS(Compensation!$C$2:$C$1514,">5")+ROWS(Compensation!$A$2:$A$1514)-COUNT(Compensation!$C$2:$C$1514) | G26: =IF(F26=E26,"PASS","FAIL") | H26: Includes non-numeric or blank values.
A27: 20 | B27: Domain | C27: SALARY blank, non-numeric or not positive | D27: Compensation | E27: 0 | F27: =COUNTIFS(Compensation!$B$2:$B$1514,"<=0")+ROWS(Compensation!$A$2:$A$1514)-COUNT(Compensation!$B$2:$B$1514) | G27: =IF(F27=E27,"PASS","FAIL") | H27: SALARY must be a positive number.
A28: 21 | B28: Domain | C28: EMPLOYMENT_TYPE not Full-Time, Part-Time or Contractor | D28: Employee_History | E28: 0 | F28: =ROWS(Employee_History!$E$2:$E$1514)-COUNTIF(Employee_History!$E$2:$E$1514,"Full-Time")-COUNTIF(Employee_History!$E$2:$E$1514,"Part-Time")-COUNTIF(Employee_History!$E$2:$E$1514,"Contractor") | G28: =IF(F28=E28,"PASS","FAIL") | H28: Allowed values per the Data Dictionary.
A29: 22 | B29: Domain | C29: EMAIL not matching first.last@ourbusiness.biz | D29: Employees | E29: 0 | F29: {=SUMPRODUCT(--(Employees!$E$2:$E$1514<>LOWER(Employees!$B$2:$B$1514&"."&Employees!$C$2:$C$1514&"@ourbusiness.biz")))} | G29: =IF(F29=E29,"PASS","FAIL") | H29: Email follows the naming convention.
A30: 23 | B30: Dates | C30: TERM_DATE before HIRE_DATE | D30: Employee_History | E30: 0 | F30: {=SUMPRODUCT((Employee_History!$D$2:$D$1514<>"")*(Employee_History!$D$2:$D$1514<Employee_History!$C$2:$C$1514))} | G30: =IF(F30=E30,"PASS","FAIL") | H30: Termination cannot precede hiring.
A31: 24 | B31: Dates | C31: HIRE_DATE before department FOUNDING_DATE | D31: Employee_History / Departments | E31: 0 | F31: {=SUMPRODUCT(--(Employee_History!$C$2:$C$1514<SUMIF(Departments!$A$2:$A$16,Employee_History!$B$2:$B$1514,Departments!$F$2:$F$16)))} | G31: =IF(F31=E31,"PASS","FAIL") | H31: Employee cannot join a department before it existed.
A32: 25 | B32: Dates | C32: Employees aged under 18 at HIRE_DATE | D32: Employee_History / Employees | E32: 0 | F32: {=SUMPRODUCT(--((Employee_History!$C$2:$C$1514-_xlfn.XLOOKUP(Employee_History!$A$2:$A$1514,Employees!$A$2:$A$1514,Employees!$D$2:$D$1514))/365.25<18))} | G32: =IF(F32=E32,"PASS","FAIL") | H32: Uses DATE_OF_BIRTH from Employees.
A33: 26 | B33: Business logic | C33: Active employees whose manager is terminated | D33: Employees / Employee_History | E33: 0 | F33: {=SUMPRODUCT((Employees!$F$2:$F$1514<>"")*(_xlfn.XLOOKUP(Employees!$F$2:$F$1514,Employee_History!$A$2:$A$1514,Employee_History!$F$2:$F$1514,"")="Terminated")*(_xlfn.XLOOKUP(Employees!$A$2:$A$1514,Employee_History!$A$2:$A$1514,Employee_History!$F$2:$F$1514,"")="Active"))} | G33: =IF(F33=E33,"PASS","FAIL") | H33: Reporting lines should be reassigned on termination.
A34: 27 | B34: Business logic | C34: Sum of department HEADCOUNT − active employees | D34: Departments / Employee_History | E34: 0 | F34: =SUM(Departments!$H$2:$H$16)-COUNTIF(Employee_History!$F$2:$F$1514,"Active") | G34: =IF(F34=E34,"PASS","FAIL") | H34: Department headcount ties to the active employee count.
A35: 28 | B35: Uniqueness | C35: Duplicate POSITION_TITLE in Positions | D35: Positions | E35: 0 | F35: =ROWS(Positions!$B$2:$B$119)-ROWS(_xlfn.UNIQUE(Positions!$B$2:$B$119)) | G35: =IF(F35=E35,"PASS","FAIL") | H35: POSITION_TITLE must be unique (one row per job title).
A36: 29 | B36: Business logic | C36: Employee counts: Positions and Locations vs Employees | D36: Positions / Locations / Employees | E36: 0 | F36: =ABS(SUM(Positions!$D$2:$D$119)-ROWS(Employees!$A$2:$A$1514))+ABS(SUM(Locations!$D$2:$D$13)-ROWS(Employees!$A$2:$A$1514)) | G36: =IF(F36=E36,"PASS","FAIL") | H36: Lookup tables account for every employee.
